Workbook
Name 공동주택동의수: 요약!#REF!
Name 공동주택토지등소유자: 요약!#REF!
Name 기타동의수: 요약!#REF!
Name 기타토지등소유자: 요약!#REF!
Name 단독_다가구동의수: 요약!#REF!
Name 단독_다가구토지등소유자: 요약!#REF!
Name 도로보정배율: 통합!$CM$3
Name 배당환산금: 통합!$BQ$3
Name 집합건축물보정배율: #REF!
Name 집합건축물보정배율: 통합!$CK$3
Name 토지등소유자: 요약!#REF!
Name 토지보정배율: #REF!
Name 토지보정배율: 통합!$CJ$3
Name 토지평당환산액: 통합!$BQ$3

Sheet 요약
B1: 구분소유자 | F1: 토지면적
A2: 구분 | B2: 구분소유자 | D2: 참석수/소유자(전체소유자) | E2: 참석수/소유자(유형별 ) | F2: 토지면적 | H2: 참석자 면적/전체소유자(토지) | I2: 참석자 면적/유형별소유자(토지) | J2: 공부상면적 | K2: 동의수 | L2: 용도별 동의율 | M2: 전체 동의중 용도별 동의율 | N2: 소유자 거주비율 | P2: 인근지역 거주비율 | R2: 외지인 비율 | T2: 40대 미만 | U2: 40대 | V2: 50대 | W2: 60대 | X2: 70대 | Y2: 80대 이상 | Z2: 용도별 건축물 | AA2: 용도별 노후 건축물 | AB2: 노후도 | AC2: 전체토지면적 동의율 | AD2: 노후건축물 소유자 동의율 | AE2: 공동주택 외 토지면적 동의율 | AF2: 공동주택 동별 과반 동의율
A3: 공동주택 | B3: {=COUNTA(_xlfn.UNIQUE(_xlfn._xlws.FILTER(표3[연번],ISNUMBER(SEARCH("공동",표3[주용도])))))-1} -> 85 | C3: =B3/$B$7 -> 0.84158416 | D3: {=IFERROR(ROWS(_xlfn.UNIQUE(_xlfn._xlws.FILTER(표3[성 명], (ISNUMBER(SEARCH("공동", 표3[주용도]))) * ((표3[1차설명회 참석자]="O") + (표3[2차설명회 참석자]="O") > 0)))), 0) / B7} -> 0.34653465 | E3: {=IFERROR(ROWS(_xlfn.UNIQUE(_xlfn._xlws.FILTER(표3[성 명], (ISNUMBER(SEARCH("공동", 표3[주용도]))) * ((표3[1차설명회 참석자]="O") + (표3[2차설명회 참석자]="O") > 0)))) / ROWS(_xlfn.UNIQUE(_xlfn._xlws.FILTER(표3[성 명], ISNUMBER(SEARCH("공동", 표3[주용도]))))), 0)} -> 0.40697674 | F3: =SUMIF(표3[주용도],"*공동*",표3[편입면적]) -> 4341.328 | G3: =F3/$F$7 -> 0.54240646 | H3: {=SUMPRODUCT((ISNUMBER(SEARCH("공동", 표3[주용도]))) * ((표3[1차설명회 참석자]="O") + (표3[2차설명회 참석자]="O") > 0), 표3[편입면적])/F7} -> 0.22808923 | I3: {=SUMPRODUCT((ISNUMBER(SEARCH("공동", 표3[주용도]))) * ((표3[1차설명회 참석자]="O") + (표3[2차설명회 참석자]="O") > 0), 표3[편입면적])/F3} -> 0.42051349 | J3: - | K3: =COUNTIFS(표3[주용도],"*공동*",표3[조합설립동의서],"O") -> 19 | L3: =K3/B3 -> 0.22352941 | M3: =K3/$B$7 -> 0.18811881 | N3: =COUNTIFS(표3[주용도],"*공동*",표3[거주중],"O") -> 36 | O3: =N3/B3 -> 0.42352941 | P3: {=COUNTA( _xlfn.UNIQUE( _xlfn._xlws.FILTER( 표3[연번], (표3[연번]<>"") * ISNUMBER(SEARCH("공동", 표3[주용도])) * (LEN(TRIM(표3[거주중]))=0) * (표3[분류2]="송파구") ) ) )} -> 38 | Q3: =P3/B3 -> 0.44705882 | R3: {=COUNTA(_xlfn.UNIQUE(_xlfn._xlws.FILTER(표3[연번], (표3[연번]<>"")*(LEN(TRIM(표3[거주중]))=0)*NOT(ISNUMBER(SEARCH("송파구",표3[분류2])))* ISNUMBER(SEARCH("공동",표3[주용도]))*NOT(ISNUMBER(SEARCH("단독",표3[주용도]))) )))} -> 15 | S3: =R3/B3 -> 0.17647059 | T3: {=COUNTA(_xlfn.UNIQUE(_xlfn._xlws.FILTER( 표3[연번], (표3[연번]<>"")* (표3[연령]="40대 미만")* ISNUMBER(SEARCH("공동",표3[주용도]))* NOT(ISNUMBER(SEARCH("단독",표3[주용도]))) )))/$B$3} -> 0.082352941 | U3: {=COUNTA(_xlfn.UNIQUE(_xlfn._xlws.FILTER( 표3[연번], (표3[연번]<>"")* (표3[연령]="40대")* ISNUMBER(SEARCH("공동",표3[주용도]))* NOT(ISNUMBER(SEARCH("단독",표3[주용도]))) )))/$B$3} -> 0.082352941 | V3: {=COUNTA(_xlfn.UNIQUE(_xlfn._xlws.FILTER( 표3[연번], (표3[연번]<>"")* (표3[연령]="50대")* ISNUMBER(SEARCH("공동",표3[주용도]))* NOT(ISNUMBER(SEARCH("단독",표3[주용도]))) )))/$B$3} -> 0.18823529 | W3: {=COUNTA(_xlfn.UNIQUE(_xlfn._xlws.FILTER( 표3[연번], (표3[연번]<>"")* (표3[연령]="60대")* ISNUMBER(SEARCH("공동",표3[주용도]))* NOT(ISNUMBER(SEARCH("단독",표3[주용도]))) )))/$B$3} -> 0.41176471 | X3: {=COUNTA(_xlfn.UNIQUE(_xlfn._xlws.FILTER( 표3[연번], (표3[연번]<>"")* (표3[연령]="70대")* ISNUMBER(SEARCH("공동",표3[주용도]))* NOT(ISNUMBER(SEARCH("단독",표3[주용도]))) )))/$B$3} -> 0.12941176 | Y3: {=COUNTA(_xlfn.UNIQUE(_xlfn._xlws.FILTER( 표3[연번], (표3[연번]<>"")* (표3[연령]="80대 이상")* ISNUMBER(SEARCH("공동",표3[주용도]))* NOT(ISNUMBER(SEARCH("단독",표3[주용도]))) )))/$B$3} -> 0.070588235 | Z3: =COUNTIFS(표3[주용도],"*공동*",표3[지상2],">0") -> 14 | AA3: =COUNTIFS(표3[주용도],"*공동*",표3[지상2],">0",표3[노후판정],"O") -> 4 | AB3: =AA7/Z7 -> 0.65517241 | AC3: =SUMIF(표3[조합설립동의서],"O",표3[편입면적])/F7 -> 0.088865978 | AD3: =COUNTIFS(표3[조합설립동의서],"O",표3[노후판정],"O")/B7 -> 0
F4: (1219.80㎡) 공동주택중 1인소유 면적 합 | G4: (15.24%)
A5: 단독/다가구 | B5: {=COUNTA(_xlfn.UNIQUE(_xlfn._xlws.FILTER(표3[연번],ISNUMBER(SEARCH("단독",표3[주용도])))))} -> 10 | C5: =B5/$B$7 -> 0.099009901 | D5: {=(SUMPRODUCT((ISNUMBER(SEARCH("단독", 표3[주용도]))) * ((표3[1차설명회 참석자]="O") + (표3[2차설명회 참석자]="O") > 0)))/B7} -> 0.02970297 | E5: {=(SUMPRODUCT((ISNUMBER(SEARCH("단독", 표3[주용도]))) * ((표3[1차설명회 참석자]="O") + (표3[2차설명회 참석자]="O") > 0)))/B5} -> 0.3 | F5: =SUMIF(표3[주용도],"*단독*",표3[편입면적]) -> 1825.5 | G5: =F5/$F$7 -> 0.22807836 | H5: {=(SUMPRODUCT((ISNUMBER(SEARCH("단독", 표3[주용도]))) * ((표3[1차설명회 참석자]="O") + (표3[2차설명회 참석자]="O") > 0), 표3[편입면적]))/F7} -> 0.064019367 | I5: {=(SUMPRODUCT((ISNUMBER(SEARCH("단독", 표3[주용도]))) * ((표3[1차설명회 참석자]="O") + (표3[2차설명회 참석자]="O") > 0), 표3[편입면적]))/F5} -> 0.28069022 | J5: - | K5: =COUNTIFS(표3[주용도],"*단독*",표3[조합설립동의서],"O") -> 0 | L5: =K5/B5 -> 0 | M5: =K5/$B$7 -> 0 | N5: =COUNTIFS(표3[주용도],"*단독*",표3[거주중],"O") -> 5 | O5: =N5/B5 -> 0.5 | P5: {=COUNTA( _xlfn.UNIQUE( _xlfn._xlws.FILTER( 표3[연번], (표3[연번]<>"") * ISNUMBER(SEARCH("단독", 표3[주용도])) * (LEN(TRIM(표3[거주중]))=0) * (표3[분류2]="송파구") ) ) )} -> 2 | Q5: =P5/B5 -> 0.2 | R5: {=COUNTA(_xlfn.UNIQUE(_xlfn._xlws.FILTER(표3[연번], (표3[연번]<>"")*(LEN(TRIM(표3[거주중]))=0)*NOT(ISNUMBER(SEARCH("송파구",표3[분류2])))* ISNUMBER(SEARCH("단독",표3[주용도]))*NOT(ISNUMBER(SEARCH("공동",표3[주용도]))) )))} -> 3 | S5: =R5/B5 -> 0.3 | T5: {=COUNTA(_xlfn.UNIQUE(_xlfn._xlws.FILTER( 표3[연번], (표3[연번]<>"")* (표3[연령]="40대 미만")* ISNUMBER(SEARCH("단독",표3[주용도]))* NOT(ISNUMBER(SEARCH("공동",표3[주용도]))) )))/$B$5} -> 0.1 | U5: {=COUNTA(_xlfn.UNIQUE(_xlfn._xlws.FILTER( 표3[연번], (표3[연번]<>"")* (표3[연령]="40대")* ISNUMBER(SEARCH("단독",표3[주용도]))* NOT(ISNUMBER(SEARCH("공동",표3[주용도]))) )))/$B$5} -> 0.1 | V5: {=COUNTA(_xlfn.UNIQUE(_xlfn._xlws.FILTER( 표3[연번], (표3[연번]<>"")* (표3[연령]="50대")* ISNUMBER(SEARCH("단독",표3[주용도]))* NOT(ISNUMBER(SEARCH("공동",표3[주용도]))) )))/$B$5} -> 0.3 | W5: {=COUNTA(_xlfn.UNIQUE(_xlfn._xlws.FILTER( 표3[연번], (표3[연번]<>"")* (표3[연령]="60대")* ISNUMBER(SEARCH("단독",표3[주용도]))* NOT(ISNUMBER(SEARCH("공동",표3[주용도]))) )))/$B$5} -> 0.2 | X5: {=COUNTA(_xlfn.UNIQUE(_xlfn._xlws.FILTER( 표3[연번], (표3[연번]<>"")* (표3[연령]="70대")* ISNUMBER(SEARCH("단독",표3[주용도]))* NOT(ISNUMBER(SEARCH("공동",표3[주용도]))) )))/$B$5} -> 0.2 | Y5: {=COUNTA(_xlfn.UNIQUE(_xlfn._xlws.FILTER( 표3[연번], (표3[연번]<>"")* (표3[연령]="80대 이상")* ISNUMBER(SEARCH("단독",표3[주용도]))* NOT(ISNUMBER(SEARCH("공동",표3[주용도]))) )))/$B$5} -> 0.2 | Z5: =COUNTIFS(표3[주용도],"*단독*",표3[지상2],">0") -> 10 | AA5: =COUNTIFS(표3[주용도],"*단독*",표3[지상2],">0",표3[노후판정],"O") -> 10
A6: 상가/기타 | B6: {=COUNTA(_xlfn.UNIQUE(_xlfn._xlws.FILTER(표3[연번],NOT(ISNUMBER(SEARCH("단독",표3[주용도])))*NOT(ISNUMBER(SEARCH("공동",표3[주용도]))))))} -> 6 | C6: =B6/$B$7 -> 0.059405941 | D6: {=(SUMPRODUCT((ISERROR(SEARCH("공동", 표3[주용도]))) * (ISERROR(SEARCH("단독", 표3[주용도]))) * ((표3[1차설명회 참석자]="O") + (표3[2차설명회 참석자]="O") > 0)))/B7} -> 0.01980198 | E6: {=(SUMPRODUCT((ISERROR(SEARCH("공동", 표3[주용도]))) * (ISERROR(SEARCH("단독", 표3[주용도]))) * ((표3[1차설명회 참석자]="O") + (표3[2차설명회 참석자]="O") > 0)))/B6} -> 0.33333333 | F6: =SUMIFS(표3[편입면적],표3[주용도],"<>*단독*",표3[주용도],"<>*공동*") -> 1837 | G6: =F6/$F$7 -> 0.22951518 | H6: {=(SUMPRODUCT((ISERROR(SEARCH("공동", 표3[주용도]))) * (ISERROR(SEARCH("단독", 표3[주용도]))) * ((표3[1차설명회 참석자]="O") + (표3[2차설명회 참석자]="O") > 0), 표3[편입면적]))/F7} -> 0.070103955 | I6: {=(SUMPRODUCT((ISERROR(SEARCH("공동", 표3[주용도]))) * (ISERROR(SEARCH("단독", 표3[주용도]))) * ((표3[1차설명회 참석자]="O") + (표3[2차설명회 참석자]="O") > 0), 표3[편입면적]))/F6} -> 0.30544366 | J6: - | K6: =COUNTIFS(표3[주용도],"<>*단독*",표3[주용도],"<>*공동*",표3[조합설립동의서],"O") -> 0 | L6: =K6/B6 -> 0 | M6: =K6/$B$7 -> 0 | N6: =COUNTIFS(표3[주용도],"<>*공동*",표3[주용도],"<>*단독*",표3[거주중],"O") -> 1 | O6: =N6/B6 -> 0.16666667 | P6: {=COUNTA(_xlfn.UNIQUE(_xlfn._xlws.FILTER(표3[연번], (표3[연번]<>"")*(LEN(TRIM(표3[거주중]))=0)*(표3[분류2]="송파구")* NOT(ISNUMBER(SEARCH("공동",표3[주용도])))* NOT(ISNUMBER(SEARCH("단독",표3[주용도]))) )))} -> 2 | Q6: =P6/B6 -> 0.33333333 | R6: {=COUNTA(_xlfn.UNIQUE(_xlfn._xlws.FILTER(표3[연번], (표3[연번]<>"")*(LEN(TRIM(표3[거주중]))=0)*NOT(ISNUMBER(SEARCH("송파구",표3[분류2])))* NOT(ISNUMBER(SEARCH("공동",표3[주용도])))* NOT(ISNUMBER(SEARCH("단독",표3[주용도]))) )))} -> 3 | S6: =R6/B6 -> 0.5 | T6: {=COUNTA(_xlfn.UNIQUE(_xlfn._xlws.FILTER( 표3[연번], (표3[연번]<>"")* (표3[연령]="40대 미만")* NOT(ISNUMBER(SEARCH("공동",표3[주용도])))* NOT(ISNUMBER(SEARCH("단독",표3[주용도]))) )))/$B$6} -> 0.16666667 | U6: {=COUNTA(_xlfn.UNIQUE(_xlfn._xlws.FILTER( 표3[연번], (표3[연번]<>"")* (표3[연령]="40대")* NOT(ISNUMBER(SEARCH("공동",표3[주용도])))* NOT(ISNUMBER(SEARCH("단독",표3[주용도]))) )))/$B$6} -> 0.16666667 | V6: {=COUNTA(_xlfn.UNIQUE(_xlfn._xlws.FILTER( 표3[연번], (표3[연번]<>"")* (표3[연령]="50대")* NOT(ISNUMBER(SEARCH("공동",표3[주용도])))* NOT(ISNUMBER(SEARCH("단독",표3[주용도]))) )))/$B$6} -> 0.16666667 | W6: {=COUNTA(_xlfn.UNIQUE(_xlfn._xlws.FILTER( 표3[연번], (표3[연번]<>"")* (표3[연령]="60대")* NOT(ISNUMBER(SEARCH("공동",표3[주용도])))* NOT(ISNUMBER(SEARCH("단독",표3[주용도]))) )))/$B$6} -> 0.16666667 | X6: {=COUNTA(_xlfn.UNIQUE(_xlfn._xlws.FILTER( 표3[연번], (표3[연번]<>"")* (표3[연령]="70대")* NOT(ISNUMBER(SEARCH("공동",표3[주용도])))* NOT(ISNUMBER(SEARCH("단독",표3[주용도]))) )))/$B$6} -> 0.16666667 | Y6: {=COUNTA(_xlfn.UNIQUE(_xlfn._xlws.FILTER( 표3[연번], (표3[연번]<>"")* (표3[연령]="80대 이상")* NOT(ISNUMBER(SEARCH("공동",표3[주용도])))* NOT(ISNUMBER(SEARCH("단독",표3[주용도]))) )))/$B$6} -> 0.16666667 | Z6: =COUNTIFS(표3[주용도],"<>*단독*",표3[주용도],"<>*공동*",표3[지상2],">0") -> 5 | AA6: =COUNTIFS(표3[주용도],"<>*공동*",표3[주용도],"<>*단독*",표3[지상2],">0",표3[노후판정],"O") -> 5
A7: 합계 | B7: =SUM(B3:B6) -> 101 | C7: =SUM(C3:C6) -> 1 | D7: =SUM(D3:D6) -> 0.3960396 | F7: =SUM(F3,F5,F6) -> 8003.828 | G7: =SUM(G3,G5,G6) -> 1 | H7: =H3+H5+H6 -> 0.36221256 | I7: {=(((SUMPRODUCT((ISERROR(SEARCH("공동", 표3[주용도]))) * (ISERROR(SEARCH("단독", 표3[주용도]))) * ((표3[1차설명회 참석자]="O") + (표3[2차설명회 참석자]="O") > 0), 표3[편입면적])))+((SUMPRODUCT((ISNUMBER(SEARCH("단독", 표3[주용도]))) * ((표3[1차설명회 참석자]="O") + (표3[2차설명회 참석자]="O") > 0), 표3[편입면적]))))/(F5+F6-통합!R155)} -> 0.33599374 | J7: =SUM(J3:J6) -> 0 | K7: =SUM(K3:K6) -> 19 | L7: - | M7: =K7/B7 -> 0.18811881 | N7: =SUM(N3:N6) -> 42 | O7: =N7/B7 -> 0.41584158 | P7: =SUM(P3:P6) -> 42 | Q7: =P7/B7 -> 0.41584158 | R7: =SUM(R3:R6) -> 21 | S7: =R7/B7 -> 0.20792079 | Z7: =SUM(Z3:Z6) -> 29 | AA7: =SUM(AA3:AA6) -> 19
B8: 전체 토지등소유자의 75% 요건 | F8: 전체 토지 2/3(67%)요건 | I8: 공동주택 외 건축물 면적 50%요건
O14: {=SUMPRODUCT((ISNUMBER(SEARCH("공동", 표3[주용도]))) * ((표3[1차설명회 참석자]="O") + (표3[2차설명회 참석자]="O") > 0), 표3[편입면적])} -> 1825.587
F34: {=(SUMPRODUCT((ISNUMBER(SEARCH("단독", 표3[주용도]))) * ((표3[1차설명회 참석자]="O") + (표3[2차설명회 참석자]="O") > 0), 표3[편입면적]))} -> 512.4 | I34: =2/3 -> 0.66666667
E35: {=(((SUMPRODUCT((ISERROR(SEARCH("공동", 표3[주용도]))) * (ISERROR(SEARCH("단독", 표3[주용도]))) * ((표3[1차설명회 참석자]="O") + (표3[2차설명회 참석자]="O") > 0), 표3[편입면적])))+((SUMPRODUCT((ISNUMBER(SEARCH("단독", 표3[주용도]))) * ((표3[1차설명회 참석자]="O") + (표3[2차설명회 참석자]="O") > 0), 표3[편입면적]))))} -> 1073.5 | F35: {=(SUMPRODUCT((ISERROR(SEARCH("공동", 표3[주용도]))) * (ISERROR(SEARCH("단독", 표3[주용도]))) * ((표3[1차설명회 참석자]="O") + (표3[2차설명회 참석자]="O") > 0), 표3[편입면적]))} -> 561.1 | G35: =F34+F35 -> 1073.5

Sheet 통합
A1: □ 송파구 문정동 28번지일대 가로주택정비사업 토지 건물 조서 | CE1: 부사장님 한글 수지분석 자료(1105자료)
A2: 기본키 | G2: 동의 | Q2: 토 지 | W2: 건 축 물 | AO2: 소유권 | CE2: 토지평당환산액 | CL2: 토지보정배율 | CM2: 집합건축물 보정배율 | CO2: 도로보정배율 | CP2: 자산평가
AC3: 노후도 | AF3: 허가유무 | AG3: 구 조 | AI3: 용 도 | AK3: 세대수 | AM3: 층 수 (지상/지하) | AO3: 소 유 자 | AU3: 거주주유·무 | BF3: 하자내역 | BK3: 지역분포도 | BV3: 건물 | BY3: 집합건물 | CE3: 31110000 | CL3: 1.7 | CM3: 1.8 | CO3: 1.3 | CS3: 종전자산평가금액 | CT3: 분양청산 | DA3: 이주비내역 | DD3: 정산잔금
A4: 공동주택 표시 | B4: 연번 | C4: 본 번 | D4: 부 번 | E4: 건물명 | F4: 호수 | G4: 징구일자 | H4: 징구현황 | I4: 성향 | J4: 대표자동의서 | K4: 조합설립동의서 | L4: 개인정보 | M4: 신분증 | N4: 접촉현황 | O4: 접촉일자 | P4: 상담내용 | Q4: 지목 | R4: 공부면적 | S4: 편입면적 | T4: 대지지분비율 | U4: 과소 필지 | V4: 공유여부 | W4: 전유면적 | X4: 지하 | Y4: 지상,지하 계 | Z4: 연면적 | AA4: 지하층용도 | AB4: 공유여부2 | AC4: 사용승인일자 | AD4: 건물연령 | AE4: 노후판정 | AF4: 허가 | AG4: 주구조 | AH4: 보조구조 | AI4: 주용도 | AJ4: 세부용도 | AK4: 세대수 | AL4: 가구수 | AM4: 지상2 | AN4: 지하3 | AO4: 성 명 | AP4: 연락처 | AQ4: 비고 | AR4: 생년월일 | AS4: 연령 | AT4: 주소 | AU4: 거주중 | AV4: 준비위원 | AW4: 1차 우편 반송자 | AX4: 1차우편 반송사유 | AY4: 2차우편 반송사유 | AZ4: 3차우편 반송자 | BA4: 1차설명회 참석자 | BB4: 2차설명회 참석자 | BC4: 열3 | BD4: 열2 | BE4: 열1 | BF4: 일자 | BG4: 등기원인 | BH4: 내역 | BI4: 금액 | BJ4: 추정실채권액 | BK4: 분류1 | BL4: 분류2 | BM4: 분류3 | BN4: 도로명 | BO4: 내부 확인 | BP4: 내부 확인2 | BQ4: 동+건물명 | BR4: 동명 | BS4: 편입면적3 | BT4: 토지단가 | BU4: 토지가액 | BV4: 주용도4 | BW4: 연면적5 | BX4: 건물가액 | BY4: 주용도6 | BZ4: 전유면적2 | CA4: 대지권면적 | CB4: 집합가액 | CC4: 종전추정가액 | CD4: 권리가액 | CE4: 토지*배당환산금 | CF4: 건물 보정 | CG4: 위치 보정 | CH4: 소형주택 보정 | CI4: 건물구조 보정 | CJ4: 경과년수 보정 | CK4: 평가금액 | CL4: 공시지가 | CM4: 공시가격 | CN4: 토지단가 (평) | CO4: 건물단가 (평) | CP4: 토지가격 | CQ4: 건물가격 | CR4: 종전자산 | CS4: 평가액-f팀 | CT4: 층 | CU4: 호수2 | CV4: 전용면적 | CW4: 계약면적 | CX4: 평가금액 (분양액) | CY4: 입주물건가액 | CZ4: 비고2 | DA4: 기지급 이주비 | DB4: 미지급 이주비 | DC4: 비고3 | DD4: 분양자잔금 | DE4: 대출이자 | DF4: 청산자잔금
B5: 1 | C5: 28 | D5: 0 | F5: 0 | Q5: 대 | R5: 233.3 | S5: 233.3 | T5: =표3[[#This Row],[편입면적]]/(SUM(표3[공부면적])) -> 0.029147926 | U5: O | W5: 341.91 | X5: 113.57 | Y5: 455.48 | Z5: 455.48 | AC5: 1989.10.19 | AD5: 36 | AE5: {=IF(표3[[#This Row],[사용승인일자]]="","", IFERROR( _xlfn.IFS( AND(ISNUMBER(SEARCH("공동",표3[[#This Row],[주용도]])), ISNUMBER(SEARCH("철",표3[[#This Row],[주구조]])), 표3[[#This Row],[건물연령]]>=30), "O", AND(ISNUMBER(SEARCH("공동",표3[[#This Row],[주용도]])), COUNTIF(표3[[#This Row],[주구조]],"<>*철*"), 표3[[#This Row],[건물연령]]>=20), "O", AND(COUNTIF(표3[[#This Row],[주용도]],"<>*공동*"), COUNTIF(표3[[#This Row],[주용도]],"<>*단독*"), ISNUMBER(SEARCH("철",표3[[#This Row],[주구조]])), 표3[[#This Row],[건물연령]]>=30), "O", AND(COUNTIF(표3[[#This Row],[주용도]],"<>*공동*"), COUNTIF(표3[[#This Row],[주구조]],"<>*철*"), 표3[[#This Row],[건물연령]]>=20), "O", AND(COUNTIF(표3[[#This Row],[주용도]],"<>*공동*"), ISNUMBER(SEARCH("주택",표3[[#This Row],[주용도]])), 표3[[#This Row],[건물연령]]>=20), "O" ), "") )} -> O | AG5: 철근콘크리트구조 | AI5: 제2종근린생활시설 | AM5: 3 | AN5: 1 | AO5: 광주이씨광천군파문정총회 | AS5: =IF( OR(표3[[#This Row],[생년월일]]="", ISBLANK(표3[[#This Row],[생년월일]])), "", IFERROR( _xlfn.LET( _xlpm.y, VALUE(표3[[#This Row],[생년월일]]), _xlpm.yyyy, IF(_xlpm.y<100, IF(_xlpm.y>25, 1900+_xlpm.y, 2000+_xlpm.y), _xlpm.y), _xlpm.age, YEAR(TODAY())-_xlpm.yyyy, IF( _xlpm.age<40,"40대 미만", IF(_xlpm.age<50,"40대", IF(_xlpm.age<60,"50대", IF(_xlpm.age<70,"60대", IF(_xlpm.age<80,"70대","80대 이상") )))) ), "") ) | AT5: 서울특별시 송파구 가락동 120-1 | AW5: =IF(COUNTIF('설명회 참석자 명부'!$W$4:$W$29,표3[[#This Row],[성 명]])>0,"O","") | AX5: =_xlfn.XLOOKUP(표3[[#This Row],[성 명]],'설명회 참석자 명부'!$W$4:$W$29,'설명회 참석자 명부'!$X$4:$X$29,"") | AZ5: O | BK5: =IFERROR(LEFT(표3[[#This Row],[주소]],FIND(" ",표3[[#This Row],[주소]])-1),"") -> 서울특별시 | BL5: =IFERROR(MID(표3[[#This Row],[주소]], FIND(" ", 표3[[#This Row],[주소]])+1, FIND(" ", 표3[[#This Row],[주소]], FIND(" ", 표3[[#This Row],[주소]])+1) - FIND(" ", 표3[[#This Row],[주소]])-1),"") -> 송파구 | BM5: =IFERROR(MID(표3[[#This Row],[주소]], FIND(" ", 표3[[#This Row],[주소]], FIND(" ", 표3[[#This Row],[주소]])+1)+1, FIND(" ", 표3[[#This Row],[주소]], FIND(" ", 표3[[#This Row],[주소]], FIND(" ", 표3[[#This Row],[주소]])+1)+1) - FIND(" ", 표3[[#This Row],[주소]], FIND(" ", 표3[[#This Row],[주소]])+1)-1),"") -> 가락동 | BS5: 233.3 | BT5: 11400000 | BU5: 2659620000 | BV5: 제2종근린생활시설 | BW5: 455.48 | BX5: 178548160 | CC5: 2838168160 | CD5: =표3[[#This Row],[종전추정가액]]*1.5219 -> 4.3194081e+09
C6: 28 | D6: 1 | E6: 청송하이츠빌B | F6: 0 | Q6: 대 | R6: 374.6 | T6: =표3[[#This Row],[편입면적]]/(SUM(표3[공부면적])) -> 0 | U6: O | Y6: 0 | Z6: 864.2 | AC6: 2002.09.05 | AD6: 23 | AE6: {=IF(표3[[#This Row],[사용승인일자]]="","", IFERROR( _xlfn.IFS( AND(ISNUMBER(SEARCH("공동",표3[[#This Row],[주용도]])), ISNUMBER(SEARCH("철",표3[[#This Row],[주구조]])), 표3[[#This Row],[건물연령]]>=30), "O", AND(ISNUMBER(SEARCH("공동",표3[[#This Row],[주용도]])), COUNTIF(표3[[#This Row],[주구조]],"<>*철*"), 표3[[#This Row],[건물연령]]>=20), "O", AND(COUNTIF(표3[[#This Row],[주용도]],"<>*공동*"), COUNTIF(표3[[#This Row],[주용도]],"<>*단독*"), ISNUMBER(SEARCH("철",표3[[#This Row],[주구조]])), 표3[[#This Row],[건물연령]]>=30), "O", AND(COUNTIF(표3[[#This Row],[주용도]],"<>*공동*"), COUNTIF(표3[[#This Row],[주구조]],"<>*철*"), 표3[[#This Row],[건물연령]]>=20), "O", AND(COUNTIF(표3[[#This Row],[주용도]],"<>*공동*"), ISNUMBER(SEARCH("주택",표3[[#This Row],[주용도]])), 표3[[#This Row],[건물연령]]>=20), "O" ), "") )} | AG6: 철근콘크리트구조 | AI6: 공동주택 | AM6: 5 | AN6: 0 | AS6: =IF( OR(표3[[#This Row],[생년월일]]="", ISBLANK(표3[[#This Row],[생년월일]])), "", IFERROR( _xlfn.LET( _xlpm.y, VALUE(표3[[#This Row],[생년월일]]), _xlpm.yyyy, IF(_xlpm.y<100, IF(_xlpm.y>25, 1900+_xlpm.y, 2000+_xlpm.y), _xlpm.y), _xlpm.age, YEAR(TODAY())-_xlpm.yyyy, IF( _xlpm.age<40,"40대 미만", IF(_xlpm.age<50,"40대", IF(_xlpm.age<60,"50대", IF(_xlpm.age<70,"60대", IF(_xlpm.age<80,"70대","80대 이상") )))) ), "") ) | AW6: =IF(COUNTIF('설명회 참석자 명부'!$W$4:$W$29,표3[[#This Row],[성 명]])>0,"O","") | AX6: =_xlfn.XLOOKUP(표3[[#This Row],[성 명]],'설명회 참석자 명부'!$W$4:$W$29,'설명회 참석자 명부'!$X$4:$X$29,"") -> 0 | BK6: =IFERROR(LEFT(표3[[#This Row],[주소]],FIND(" ",표3[[#This Row],[주소]])-1),"") | BL6: =IFERROR(MID(표3[[#This Row],[주소]], FIND(" ", 표3[[#This Row],[주소]])+1, FIND(" ", 표3[[#This Row],[주소]], FIND(" ", 표3[[#This Row],[주소]])+1) - FIND(" ", 표3[[#This Row],[주소]])-1),"") | BM6: =IFERROR(MID(표3[[#This Row],[주소]], FIND(" ", 표3[[#This Row],[주소]], FIND(" ", 표3[[#This Row],[주소]])+1)+1, FIND(" ", 표3[[#This Row],[주소]], FIND(" ", 표3[[#This Row],[주소]], FIND(" ", 표3[[#This Row],[주소]])+1)+1) - FIND(" ", 표3[[#This Row],[주소]], FIND(" ", 표3[[#This Row],[주소]])+1)-1),"") | CD6: =표3[[#This Row],[종전추정가액]]*1.5219 -> 0
B7: 2 | C7: 28 | D7: 1 | E7: 청송하이츠빌B | F7: 101 | R7: 0 | S7: 44.45 | T7: =표3[[#This Row],[편입면적]]/(SUM(표3[공부면적])) -> 0.0055534733 | W7: 94.8 | X7: 7.47 | Y7: 102.27 | AE7: {=IF(표3[[#This Row],[사용승인일자]]="","", IFERROR( _xlfn.IFS( AND(ISNUMBER(SEARCH("공동",표3[[#This Row],[주용도]])), ISNUMBER(SEARCH("철",표3[[#This Row],[주구조]])), 표3[[#This Row],[건물연령]]>=30), "O", AND(ISNUMBER(SEARCH("공동",표3[[#This Row],[주용도]])), COUNTIF(표3[[#This Row],[주구조]],"<>*철*"), 표3[[#This Row],[건물연령]]>=20), "O", AND(COUNTIF(표3[[#This Row],[주용도]],"<>*공동*"), COUNTIF(표3[[#This Row],[주용도]],"<>*단독*"), ISNUMBER(SEARCH("철",표3[[#This Row],[주구조]])), 표3[[#This Row],[건물연령]]>=30), "O", AND(COUNTIF(표3[[#This Row],[주용도]],"<>*공동*"), COUNTIF(표3[[#This Row],[주구조]],"<>*철*"), 표3[[#This Row],[건물연령]]>=20), "O", AND(COUNTIF(표3[[#This Row],[주용도]],"<>*공동*"), ISNUMBER(SEARCH("주택",표3[[#This Row],[주용도]])), 표3[[#This Row],[건물연령]]>=20), "O" ), "") )} | AG7: 철근콘크리트구조 | AI7: 공동주택 | AO7: 이종학 | AR7: 49 | AS7: =IF( OR(표3[[#This Row],[생년월일]]="", ISBLANK(표3[[#This Row],[생년월일]])), "", IFERROR( _xlfn.LET( _xlpm.y, VALUE(표3[[#This Row],[생년월일]]), _xlpm.yyyy, IF(_xlpm.y<100, IF(_xlpm.y>25, 1900+_xlpm.y, 2000+_xlpm.y), _xlpm.y), _xlpm.age, YEAR(TODAY())-_xlpm.yyyy, IF( _xlpm.age<40,"40대 미만", IF(_xlpm.age<50,"40대", IF(_xlpm.age<60,"50대", IF(_xlpm.age<70,"60대", IF(_xlpm.age<80,"70대","80대 이상") )))) ), "") ) -> 70대 | AT7: 서울 송파구 문정동 4-3 | AW7: =IF(COUNTIF('설명회 참석자 명부'!$W$4:$W$29,표3[[#This Row],[성 명]])>0,"O","") | AX7: =_xlfn.XLOOKUP(표3[[#This Row],[성 명]],'설명회 참석자 명부'!$W$4:$W$29,'설명회 참석자 명부'!$X$4:$X$29,"") | AZ7: O | BK7: =IFERROR(LEFT(표3[[#This Row],[주소]],FIND(" ",표3[[#This Row],[주소]])-1),"") -> 서울 | BL7: =IFERROR(MID(표3[[#This Row],[주소]], FIND(" ", 표3[[#This Row],[주소]])+1, FIND(" ", 표3[[#This Row],[주소]], FIND(" ", 표3[[#This Row],[주소]])+1) - FIND(" ", 표3[[#This Row],[주소]])-1),"") -> 송파구 | BM7: =IFERROR(MID(표3[[#This Row],[주소]], FIND(" ", 표3[[#This Row],[주소]], FIND(" ", 표3[[#This Row],[주소]])+1)+1, FIND(" ", 표3[[#This Row],[주소]], FIND(" ", 표3[[#This Row],[주소]], FIND(" ", 표3[[#This Row],[주소]])+1)+1) - FIND(" ", 표3[[#This Row],[주소]], FIND(" ", 표3[[#This Row],[주소]])+1)-1),"") -> 문정동 | BY7: 근린생활시설 | BZ7: 94.8 | CA7: 44.45 | CB7: 669000000 | CC7: 669000000 | CD7: =표3[[#This Row],[종전추정가액]]*1.5219 -> 1018151100
B8: 2 | C8: 28 | D8: 1 | E8: 청송하이츠빌B | F8: 102 | R8: 0 | S8: 44.45 | T8: =표3[[#This Row],[편입면적]]/(SUM(표3[공부면적])) -> 0.0055534733 | W8: 94.8 | X8: 7.47 | Y8: 102.27 | AE8: {=IF(표3[[#This Row],[사용승인일자]]="","", IFERROR( _xlfn.IFS( AND(ISNUMBER(SEARCH("공동",표3[[#This Row],[주용도]])), ISNUMBER(SEARCH("철",표3[[#This Row],[주구조]])), 표3[[#This Row],[건물연령]]>=30), "O", AND(ISNUMBER(SEARCH("공동",표3[[#This Row],[주용도]])), COUNTIF(표3[[#This Row],[주구조]],"<>*철*"), 표3[[#This Row],[건물연령]]>=20), "O", AND(COUNTIF(표3[[#This Row],[주용도]],"<>*공동*"), COUNTIF(표3[[#This Row],[주용도]],"<>*단독*"), ISNUMBER(SEARCH("철",표3[[#This Row],[주구조]])), 표3[[#This Row],[건물연령]]>=30), "O", AND(COUNTIF(표3[[#This Row],[주용도]],"<>*공동*"), COUNTIF(표3[[#This Row],[주구조]],"<>*철*"), 표3[[#This Row],[건물연령]]>=20), "O", AND(COUNTIF(표3[[#This Row],[주용도]],"<>*공동*"), ISNUMBER(SEARCH("주택",표3[[#This Row],[주용도]])), 표3[[#This Row],[건물연령]]>=20), "O" ), "") )} | AG8: 철근콘크리트구조 | AI8: 공동주택 | AO8: 이종학 | AS8: =IF( OR(표3[[#This Row],[생년월일]]="", ISBLANK(표3[[#This Row],[생년월일]])), "", IFERROR( _xlfn.LET( _xlpm.y, VALUE(표3[[#This Row],[생년월일]]), _xlpm.yyyy, IF(_xlpm.y<100, IF(_xlpm.y>25, 1900+_xlpm.y, 2000+_xlpm.y), _xlpm.y), _xlpm.age, YEAR(TODAY())-_xlpm.yyyy, IF( _xlpm.age<40,"40대 미만", IF(_xlpm.age<50,"40대", IF(_xlpm.age<60,"50대", IF(_xlpm.age<70,"60대", IF(_xlpm.age<80,"70대","80대 이상") )))) ), "") ) | AT8: 서울 송파구 문정동 4-3 | AW8: =IF(COUNTIF('설명회 참석자 명부'!$W$4:$W$29,표3[[#This Row],[성 명]])>0,"O","") | AX8: =_xlfn.XLOOKUP(표3[[#This Row],[성 명]],'설명회 참석자 명부'!$W$4:$W$29,'설명회 참석자 명부'!$X$4:$X$29,"") | BK8: =IFERROR(LEFT(표3[[#This Row],[주소]],FIND(" ",표3[[#This Row],[주소]])-1),"") -> 서울 | BL8: =IFERROR(MID(표3[[#This Row],[주소]], FIND(" ", 표3[[#This Row],[주소]])+1, FIND(" ", 표3[[#This Row],[주소]], FIND(" ", 표3[[#This Row],[주소]])+1) - FIND(" ", 표3[[#This Row],[주소]])-1),"") -> 송파구 | BM8: =IFERROR(MID(표3[[#This Row],[주소]], FIND(" ", 표3[[#This Row],[주소]], FIND(" ", 표3[[#This Row],[주소]])+1)+1, FIND(" ", 표3[[#This Row],[주소]], FIND(" ", 표3[[#This Row],[주소]], FIND(" ", 표3[[#This Row],[주소]])+1)+1) - FIND(" ", 표3[[#This Row],[주소]], FIND(" ", 표3[[#This Row],[주소]])+1)-1),"") -> 문정동 | BY8: 근린생활시설 | BZ8: 94.8 | CA8: 44.45 | CB8: 669000000 | CC8: 669000000 | CD8: =표3[[#This Row],[종전추정가액]]*1.5219 -> 1018151100
B9: 3 | C9: 28 | D9: 1 | E9: 청송하이츠빌B | F9: 201 | R9: 0 | S9: 35.71 | T9: =표3[[#This Row],[편입면적]]/(SUM(표3[공부면적])) -> 0.0044615192 | W9: 76.2 | X9: 6.19 | Y9: 82.39 | AE9: {=IF(표3[[#This Row],[사용승인일자]]="","", IFERROR( _xlfn.IFS( AND(ISNUMBER(SEARCH("공동",표3[[#This Row],[주용도]])), ISNUMBER(SEARCH("철",표3[[#This Row],[주구조]])), 표3[[#This Row],[건물연령]]>=30), "O", AND(ISNUMBER(SEARCH("공동",표3[[#This Row],[주용도]])), COUNTIF(표3[[#This Row],[주구조]],"<>*철*"), 표3[[#This Row],[건물연령]]>=20), "O", AND(COUNTIF(표3[[#This Row],[주용도]],"<>*공동*"), COUNTIF(표3[[#This Row],[주용도]],"<>*단독*"), ISNUMBER(SEARCH("철",표3[[#This Row],[주구조]])), 표3[[#This Row],[건물연령]]>=30), "O", AND(COUNTIF(표3[[#This Row],[주용도]],"<>*공동*"), COUNTIF(표3[[#This Row],[주구조]],"<>*철*"), 표3[[#This Row],[건물연령]]>=20), "O", AND(COUNTIF(표3[[#This Row],[주용도]],"<>*공동*"), ISNUMBER(SEARCH("주택",표3[[#This Row],[주용도]])), 표3[[#This Row],[건물연령]]>=20), "O" ), "") )} | AG9: 철근콘크리트구조 | AI9: 공동주택 | AO9: 송점아 | AP9: 1041834048 | AR9: 57 | AS9: =IF( OR(표3[[#This Row],[생년월일]]="", ISBLANK(표3[[#This Row],[생년월일]])), "", IFERROR( _xlfn.LET( _xlpm.y, VALUE(표3[[#This Row],[생년월일]]), _xlpm.yyyy, IF(_xlpm.y<100, IF(_xlpm.y>25, 1900+_xlpm.y, 2000+_xlpm.y), _xlpm.y), _xlpm.age, YEAR(TODAY())-_xlpm.yyyy, IF( _xlpm.age<40,"40대 미만", IF(_xlpm.age<50,"40대", IF(_xlpm.age<60,"50대", IF(_xlpm.age<70,"60대", IF(_xlpm.age<80,"70대","80대 이상") )))) ), "") ) -> 60대 | AT9: 서울특별시 송파구 동남로8길 10, 201호(문정동,청송하이츠빌라) | AU9: O | AW9: =IF(COUNTIF('설명회 참석자 명부'!$W$4:$W$29,표3[[#This Row],[성 명]])>0,"O","") | AX9: =_xlfn.XLOOKUP(표3[[#This Row],[성 명]],'설명회 참석자 명부'!$W$4:$W$29,'설명회 참석자 명부'!$X$4:$X$29,"") | BA9: O | BK9: =IFERROR(LEFT(표3[[#This Row],[주소]],FIND(" ",표3[[#This Row],[주소]])-1),"") -> 서울특별시 | BL9: =IFERROR(MID(표3[[#This Row],[주소]], FIND(" ", 표3[[#This Row],[주소]])+1, FIND(" ", 표3[[#This Row],[주소]], FIND(" ", 표3[[#This Row],[주소]])+1) - FIND(" ", 표3[[#This Row],[주소]])-1),"") -> 송파구 | BM9: =IFERROR(MID(표3[[#This Row],[주소]], FIND(" ", 표3[[#This Row],[주소]], FIND(" ", 표3[[#This Row],[주소]])+1)+1, FIND(" ", 표3[[#This Row],[주소]], FIND(" ", 표3[[#This Row],[주소]], FIND(" ", 표3[[#This Row],[주소]])+1)+1) - FIND(" ", 표3[[#This Row],[주소]], FIND(" ", 표3[[#This Row],[주소]])+1)-1),"") -> 동남로8길 | BY9: 다세대 | BZ9: 76.2 | CA9: 35.71 | CB9: 552000000 | CC9: 552000000 | CD9: =표3[[#This Row],[종전추정가액]]*1.5219 -> 840088800
B10: 4 | C10: 28 | D10: 1 | E10: 청송하이츠빌B | F10: 202 | R10: 0 | S10: 35.71 | T10: =표3[[#This Row],[편입면적]]/(SUM(표3[공부면적])) -> 0.0044615192 | W10: 76.2 | X10: 6.19 | Y10: 82.39 | AE10: {=IF(표3[[#This Row],[사용승인일자]]="","", IFERROR( _xlfn.IFS( AND(ISNUMBER(SEARCH("공동",표3[[#This Row],[주용도]])), ISNUMBER(SEARCH("철",표3[[#This Row],[주구조]])), 표3[[#This Row],[건물연령]]>=30), "O", AND(ISNUMBER(SEARCH("공동",표3[[#This Row],[주용도]])), COUNTIF(표3[[#This Row],[주구조]],"<>*철*"), 표3[[#This Row],[건물연령]]>=20), "O", AND(COUNTIF(표3[[#This Row],[주용도]],"<>*공동*"), COUNTIF(표3[[#This Row],[주용도]],"<>*단독*"), ISNUMBER(SEARCH("철",표3[[#This Row],[주구조]])), 표3[[#This Row],[건물연령]]>=30), "O", AND(COUNTIF(표3[[#This Row],[주용도]],"<>*공동*"), COUNTIF(표3[[#This Row],[주구조]],"<>*철*"), 표3[[#This Row],[건물연령]]>=20), "O", AND(COUNTIF(표3[[#This Row],[주용도]],"<>*공동*"), ISNUMBER(SEARCH("주택",표3[[#This Row],[주용도]])), 표3[[#This Row],[건물연령]]>=20), "O" ), "") )} | AG10: 철근콘크리트구조 | AI10: 공동주택 | AO10: 배홍숙 | AP10: 1089568848 | AR10: 60 | AS10: =IF( OR(표3[[#This Row],[생년월일]]="", ISBLANK(표3[[#This Row],[생년월일]])), "", IFERROR( _xlfn.LET( _xlpm.y, VALUE(표3[[#This Row],[생년월일]]), _xlpm.yyyy, IF(_xlpm.y<100, IF(_xlpm.y>25, 1900+_xlpm.y, 2000+_xlpm.y), _xlpm.y), _xlpm.age, YEAR(TODAY())-_xlpm.yyyy, IF( _xlpm.age<40,"40대 미만", IF(_xlpm.age<50,"40대", IF(_xlpm.age<60,"50대", IF(_xlpm.age<70,"60대", IF(_xlpm.age<80,"70대","80대 이상") )))) ), "") ) -> 60대 | AT10: 서울특별시 송파구 가락동 103-10 302호 | AW10: =IF(COUNTIF('설명회 참석자 명부'!$W$4:$W$29,표3[[#This Row],[성 명]])>0,"O","") | AX10: =_xlfn.XLOOKUP(표3[[#This Row],[성 명]],'설명회 참석자 명부'!$W$4:$W$29,'설명회 참석자 명부'!$X$4:$X$29,"") | AZ10: O | BK10: =IFERROR(LEFT(표3[[#This Row],[주소]],FIND(" ",표3[[#This Row],[주소]])-1),"") -> 서울특별시 | BL10: =IFERROR(MID(표3[[#This Row],[주소]], FIND(" ", 표3[[#This Row],[주소]])+1, FIND(" ", 표3[[#This Row],[주소]], FIND(" ", 표3[[#This Row],[주소]])+1) - FIND(" ", 표3[[#This Row],[주소]])-1),"") -> 송파구 | BM10: =IFERROR(MID(표3[[#This Row],[주소]], FIND(" ", 표3[[#This Row],[주소]], FIND(" ", 표3[[#This Row],[주소]])+1)+1, FIND(" ", 표3[[#This Row],[주소]], FIND(" ", 표3[[#This Row],[주소]], FIND(" ", 표3[[#This Row],[주소]])+1)+1) - FIND(" ", 표3[[#This Row],[주소]], FIND(" ", 표3[[#This Row],[주소]])+1)-1),"") -> 가락동 | BY10: 다세대 | BZ10: 76.2 | CA10: 35.71 | CB10: 552000000 | CC10: 552000000 | CD10: =표3[[#This Row],[종전추정가액]]*1.5219 -> 840088800
B11: 5 | C11: 28 | D11: 1 | E11: 청송하이츠빌B | F11: 301 | P11: [2026.04.13 17:18] 이민후 팀장: 4-13 준비위 간담회 참석 | R11: 0 | S11: 35.71 | T11: =표3[[#This Row],[편입면적]]/(SUM(표3[공부면적])) -> 0.0044615192 | W11: 76.2 | X11: 6.19 | Y11: 82.39 | AE11: {=IF(표3[[#This Row],[사용승인일자]]="","", IFERROR( _xlfn.IFS( AND(ISNUMBER(SEARCH("공동",표3[[#This Row],[주용도]])), ISNUMBER(SEARCH("철",표3[[#This Row],[주구조]])), 표3[[#This Row],[건물연령]]>=30), "O", AND(ISNUMBER(SEARCH("공동",표3[[#This Row],[주용도]])), COUNTIF(표3[[#This Row],[주구조]],"<>*철*"), 표3[[#This Row],[건물연령]]>=20), "O", AND(COUNTIF(표3[[#This Row],[주용도]],"<>*공동*"), COUNTIF(표3[[#This Row],[주용도]],"<>*단독*"), ISNUMBER(SEARCH("철",표3[[#This Row],[주구조]])), 표3[[#This Row],[건물연령]]>=30), "O", AND(COUNTIF(표3[[#This Row],[주용도]],"<>*공동*"), COUNTIF(표3[[#This Row],[주구조]],"<>*철*"), 표3[[#This Row],[건물연령]]>=20), "O", AND(COUNTIF(표3[[#This Row],[주용도]],"<>*공동*"), ISNUMBER(SEARCH("주택",표3[[#This Row],[주용도]])), 표3[[#This Row],[건물연령]]>=20), "O" ), "") )} | AG11: 철근콘크리트구조 | AI11: 공동주택 | AO11: 양명숙 | AP11: 010-2520-6793 010-3710-6773 010-4188-6793 | AQ11: 소유주 아들 전화번호 | AR11: 61 | AS11: =IF( OR(표3[[#This Row],[생년월일]]="", ISBLANK(표3[[#This Row],[생년월일]])), "", IFERROR( _xlfn.LET( _xlpm.y, VALUE(표3[[#This Row],[생년월일]]), _xlpm.yyyy, IF(_xlpm.y<100, IF(_xlpm.y>25, 1900+_xlpm.y, 2000+_xlpm.y), _xlpm.y), _xlpm.age, YEAR(TODAY())-_xlpm.yyyy, IF( _xlpm.age<40,"40대 미만", IF(_xlpm.age<50,"40대", IF(_xlpm.age<60,"50대", IF(_xlpm.age<70,"60대", IF(_xlpm.age<80,"70대","80대 이상") )))) ), "") ) -> 60대 | AT11: 서울특별시 송파구 문정동28-1 301호 | AU11: O | AV11: O | AW11: =IF(COUNTIF('설명회 참석자 명부'!$W$4:$W$29,표3[[#This Row],[성 명]])>0,"O","") | AX11: =_xlfn.XLOOKUP(표3[[#This Row],[성 명]],'설명회 참석자 명부'!$W$4:$W$29,'설명회 참석자 명부'!$X$4:$X$29,"") | BB11: O | BK11: =IFERROR(LEFT(표3[[#This Row],[주소]],FIND(" ",표3[[#This Row],[주소]])-1),"") -> 서울특별시 | BL11: =IFERROR(MID(표3[[#This Row],[주소]], FIND(" ", 표3[[#This Row],[주소]])+1, FIND(" ", 표3[[#This Row],[주소]], FIND(" ", 표3[[#This Row],[주소]])+1) - FIND(" ", 표3[[#This Row],[주소]])-1),"") -> 송파구 | BM11: =IFERROR(MID(표3[[#This Row],[주소]], FIND(" ", 표3[[#This Row],[주소]], FIND(" ", 표3[[#This Row],[주소]])+1)+1, FIND(" ", 표3[[#This Row],[주소]], FIND(" ", 표3[[#This Row],[주소]], FIND(" ", 표3[[#This Row],[주소]])+1)+1) - FIND(" ", 표3[[#This Row],[주소]], FIND(" ", 표3[[#This Row],[주소]])+1)-1),"") -> 문정동28-1 | BY11: 다세대 | BZ11: 76.2 | CA11: 35.71 | CB11: 557000000 | CC11: 557000000 | CD11: =표3[[#This Row],[종전추정가액]]*1.5219 -> 847698300
B12: 6 | C12: 28 | D12: 1 | E12: 청송하이츠빌B | F12: 302 | R12: 0 | S12: 35.71 | T12: =표3[[#This Row],[편입면적]]/(SUM(표3[공부면적])) -> 0.0044615192 | W12: 76.2 | X12: 6.19 | Y12: 82.39 | AE12: {=IF(표3[[#This Row],[사용승인일자]]="","", IFERROR( _xlfn.IFS( AND(ISNUMBER(SEARCH("공동",표3[[#This Row],[주용도]])), ISNUMBER(SEARCH("철",표3[[#This Row],[주구조]])), 표3[[#This Row],[건물연령]]>=30), "O", AND(ISNUMBER(SEARCH("공동",표3[[#This Row],[주용도]])), COUNTIF(표3[[#This Row],[주구조]],"<>*철*"), 표3[[#This Row],[건물연령]]>=20), "O", AND(COUNTIF(표3[[#This Row],[주용도]],"<>*공동*"), COUNTIF(표3[[#This Row],[주용도]],"<>*단독*"), ISNUMBER(SEARCH("철",표3[[#This Row],[주구조]])), 표3[[#This Row],[건물연령]]>=30), "O", AND(COUNTIF(표3[[#This Row],[주용도]],"<>*공동*"), COUNTIF(표3[[#This Row],[주구조]],"<>*철*"), 표3[[#This Row],[건물연령]]>=20), "O", AND(COUNTIF(표3[[#This Row],[주용도]],"<>*공동*"), ISNUMBER(SEARCH("주택",표3[[#This Row],[주용도]])), 표3[[#This Row],[건물연령]]>=20), "O" ), "") )} | AG12: 철근콘크리트구조 | AI12: 공동주택 | AO12: 오우진 | AR12: 91 | AS12: =IF( OR(표3[[#This Row],[생년월일]]="", ISBLANK(표3[[#This Row],[생년월일]])), "", IFERROR( _xlfn.LET( _xlpm.y, VALUE(표3[[#This Row],[생년월일]]), _xlpm.yyyy, IF(_xlpm.y<100, IF(_xlpm.y>25, 1900+_xlpm.y, 2000+_xlpm.y), _xlpm.y), _xlpm.age, YEAR(TODAY())-_xlpm.yyyy, IF( _xlpm.age<40,"40대 미만", IF(_xlpm.age<50,"40대", IF(_xlpm.age<60,"50대", IF(_xlpm.age<70,"60대", IF(_xlpm.age<80,"70대","80대 이상") )))) ), "") ) -> 40대 미만 | AT12: 서울특별시 송파구 백제고분로27길 16-12, 202호 (삼전동) | AW12: =IF(COUNTIF('설명회 참석자 명부'!$W$4:$W$29,표3[[#This Row],[성 명]])>0,"O","") | AX12: =_xlfn.XLOOKUP(표3[[#This Row],[성 명]],'설명회 참석자 명부'!$W$4:$W$29,'설명회 참석자 명부'!$X$4:$X$29,"") | BK12: =IFERROR(LEFT(표3[[#This Row],[주소]],FIND(" ",표3[[#This Row],[주소]])-1),"") -> 서울특별시 | BL12: =IFERROR(MID(표3[[#This Row],[주소]], FIND(" ", 표3[[#This Row],[주소]])+1, FIND(" ", 표3[[#This Row],[주소]], FIND(" ", 표3[[#This Row],[주소]])+1) - FIND(" ", 표3[[#This Row],[주소]])-1),"") -> 송파구 | BM12: =IFERROR(MID(표3[[#This Row],[주소]], FIND(" ", 표3[[#This Row],[주소]], FIND(" ", 표3[[#This Row],[주소]])+1)+1, FIND(" ", 표3[[#This Row],[주소]], FIND(" ", 표3[[#This Row],[주소]], FIND(" ", 표3[[#This Row],[주소]])+1)+1) - FIND(" ", 표3[[#This Row],[주소]], FIND(" ", 표3[[#This Row],[주소]])+1)-1),"") -> 백제고분로27길 | BY12: 다세대 | BZ12: 76.2 | CA12: 35.71 | CB12: 557000000 | CC12: 557000000 | CD12: =표3[[#This Row],[종전추정가액]]*1.5219 -> 847698300
B13: 7 | C13: 28 | D13: 1 | E13: 청송하이츠빌B | F13: 401 | K13: O | P13: [2026.04.13 17:20] 이민후 팀장: 4-13 간담회 참석 [2026.04.15 15:59] 이민후 팀장: 신분증 사본 요청 필요 | R13: 0 | S13: 35.71 | T13: =표3[[#This Row],[편입면적]]/(SUM(표3[공부면적])) -> 0.0044615192 | W13: 76.2 | X13: 6.19 | Y13: 82.39 | AE13: {=IF(표3[[#This Row],[사용승인일자]]="","", IFERROR( _xlfn.IFS( AND(ISNUMBER(SEARCH("공동",표3[[#This Row],[주용도]])), ISNUMBER(SEARCH("철",표3[[#This Row],[주구조]])), 표3[[#This Row],[건물연령]]>=30), "O", AND(ISNUMBER(SEARCH("공동",표3[[#This Row],[주용도]])), COUNTIF(표3[[#This Row],[주구조]],"<>*철*"), 표3[[#This Row],[건물연령]]>=20), "O", AND(COUNTIF(표3[[#This Row],[주용도]],"<>*공동*"), COUNTIF(표3[[#This Row],[주용도]],"<>*단독*"), ISNUMBER(SEARCH("철",표3[[#This Row],[주구조]])), 표3[[#This Row],[건물연령]]>=30), "O", AND(COUNTIF(표3[[#This Row],[주용도]],"<>*공동*"), COUNTIF(표3[[#This Row],[주구조]],"<>*철*"), 표3[[#This Row],[건물연령]]>=20), "O", AND(COUNTIF(표3[[#This Row],[주용도]],"<>*공동*"), ISNUMBER(SEARCH("주택",표3[[#This Row],[주용도]])), 표3[[#This Row],[건물연령]]>=20), "O" ), "") )} | AG13: 철근콘크리트구조 | AI13: 공동주택 | AO13: 이숙현 | AP13: 010-6266-4936 010-4747-6757 | AQ13: 남편 김창섭 준비위원 | AR13: 65 | AS13: =IF( OR(표3[[#This Row],[생년월일]]="", ISBLANK(표3[[#This Row],[생년월일]])), "", IFERROR( _xlfn.LET( _xlpm.y, VALUE(표3[[#This Row],[생년월일]]), _xlpm.yyyy, IF(_xlpm.y<100, IF(_xlpm.y>25, 1900+_xlpm.y, 2000+_xlpm.y), _xlpm.y), _xlpm.age, YEAR(TODAY())-_xlpm.yyyy, IF( _xlpm.age<40,"40대 미만", IF(_xlpm.age<50,"40대", IF(_xlpm.age<60,"50대", IF(_xlpm.age<70,"60대", IF(_xlpm.age<80,"70대","80대 이상") )))) ), "") ) -> 60대 | AT13: 서울특별시 송파구 동남로8길 10,401호(문정동,청송빌라) | AU13: O | AV13: O | AW13: =IF(COUNTIF('설명회 참석자 명부'!$W$4:$W$29,표3[[#This Row],[성 명]])>0,"O","") | BA13: O | BB13: O | BK13: =IFERROR(LEFT(표3[[#This Row],[주소]],FIND(" ",표3[[#This Row],[주소]])-1),"") -> 서울특별시 | BL13: =IFERROR(MID(표3[[#This Row],[주소]], FIND(" ", 표3[[#This Row],[주소]])+1, FIND(" ", 표3[[#This Row],[주소]], FIND(" ", 표3[[#This Row],[주소]])+1) - FIND(" ", 표3[[#This Row],[주소]])-1),"") -> 송파구 | BM13: =IFERROR(MID(표3[[#This Row],[주소]], FIND(" ", 표3[[#This Row],[주소]], FIND(" ", 표3[[#This Row],[주소]])+1)+1, FIND(" ", 표3[[#This Row],[주소]], FIND(" ", 표3[[#This Row],[주소]], FIND(" ", 표3[[#This Row],[주소]])+1)+1) - FIND(" ", 표3[[#This Row],[주소]], FIND(" ", 표3[[#This Row],[주소]])+1)-1),"") -> 동남로8길 | BY13: 다세대 | BZ13: 76.2 | CA13: 35.71 | CB13: 557000000 | CC13: 557000000 | CD13: =표3[[#This Row],[종전추정가액]]*1.5219 -> 847698300
B14: 8 | C14: 28 | D14: 1 | E14: 청송하이츠빌B | F14: 402 | K14: O | L14: O | M14: O | R14: 0 | S14: 35.71 | T14: =표3[[#This Row],[편입면적]]/(SUM(표3[공부면적])) -> 0.0044615192 | W14: 76.2 | X14: 6.19 | Y14: 82.39 | AE14: {=IF(표3[[#This Row],[사용승인일자]]="","", IFERROR( _xlfn.IFS( AND(ISNUMBER(SEARCH("공동",표3[[#This Row],[주용도]])), ISNUMBER(SEARCH("철",표3[[#This Row],[주구조]])), 표3[[#This Row],[건물연령]]>=30), "O", AND(ISNUMBER(SEARCH("공동",표3[[#This Row],[주용도]])), COUNTIF(표3[[#This Row],[주구조]],"<>*철*"), 표3[[#This Row],[건물연령]]>=20), "O", AND(COUNTIF(표3[[#This Row],[주용도]],"<>*공동*"), COUNTIF(표3[[#This Row],[주용도]],"<>*단독*"), ISNUMBER(SEARCH("철",표3[[#This Row],[주구조]])), 표3[[#This Row],[건물연령]]>=30), "O", AND(COUNTIF(표3[[#This Row],[주용도]],"<>*공동*"), COUNTIF(표3[[#This Row],[주구조]],"<>*철*"), 표3[[#This Row],[건물연령]]>=20), "O", AND(COUNTIF(표3[[#This Row],[주용도]],"<>*공동*"), ISNUMBER(SEARCH("주택",표3[[#This Row],[주용도]])), 표3[[#This Row],[건물연령]]>=20), "O" ), "") )} | AG14: 철근콘크리트구조 | AI14: 공동주택 | AO14: 김병기 | AP14: 1088475510 | AR14: 65 | AS14: =IF( OR(표3[[#This Row],[생년월일]]="", ISBLANK(표3[[#This Row],[생년월일]])), "", IFERROR( _xlfn.LET( _xlpm.y, VALUE(표3[[#This Row],[생년월일]]), _xlpm.yyyy, IF(_xlpm.y<100, IF(_xlpm.y>25, 1900+_xlpm.y, 2000+_xlpm.y), _xlpm.y), _xlpm.age, YEAR(TODAY())-_xlpm.yyyy, IF( _xlpm.age<40,"40대 미만", IF(_xlpm.age<50,"40대", IF(_xlpm.age<60,"50대", IF(_xlpm.age<70,"60대", IF(_xlpm.age<80,"70대","80대 이상") )))) ), "") ) -> 60대 | AT14: 서울특별시 송파구 문정동28-1 402호 | AW14: =IF(COUNTIF('설명회 참석자 명부'!$W$4:$W$29,표3[[#This Row],[성 명]])>0,"O","") | BA14: O | BB14: O | BK14: =IFERROR(LEFT(표3[[#This Row],[주소]],FIND(" ",표3[[#This Row],[주소]])-1),"") -> 서울특별시 | BL14: =IFERROR(MID(표3[[#This Row],[주소]], FIND(" ", 표3[[#This Row],[주소]])+1, FIND(" ", 표3[[#This Row],[주소]], FIND(" ", 표3[[#This Row],[주소]])+1) - FIND(" ", 표3[[#This Row],[주소]])-1),"") -> 송파구 | BM14: =IFERROR(MID(표3[[#This Row],[주소]], FIND(" ", 표3[[#This Row],[주소]], FIND(" ", 표3[[#This Row],[주소]])+1)+1, FIND(" ", 표3[[#This Row],[주소]], FIND(" ", 표3[[#This Row],[주소]], FIND(" ", 표3[[#This Row],[주소]])+1)+1) - FIND(" ", 표3[[#This Row],[주소]], FIND(" ", 표3[[#This Row],[주소]])+1)-1),"") -> 문정동28-1 | BY14: 다세대 | BZ14: 76.2 | CA14: 35.71 | CB14: 557000000 | CC14: 557000000 | CD14: =표3[[#This Row],[종전추정가액]]*1.5219 -> 847698300
B15: 9 | C15: 28 | D15: 1 | E15: 청송하이츠빌B | F15: 501 | R15: 0 | S15: 35.71 | T15: =표3[[#This Row],[편입면적]]/(SUM(표3[공부면적])) -> 0.0044615192 | W15: 76.2 | X15: 6.19 | Y15: 82.39 | AE15: {=IF(표3[[#This Row],[사용승인일자]]="","", IFERROR( _xlfn.IFS( AND(ISNUMBER(SEARCH("공동",표3[[#This Row],[주용도]])), ISNUMBER(SEARCH("철",표3[[#This Row],[주구조]])), 표3[[#This Row],[건물연령]]>=30), "O", AND(ISNUMBER(SEARCH("공동",표3[[#This Row],[주용도]])), COUNTIF(표3[[#This Row],[주구조]],"<>*철*"), 표3[[#This Row],[건물연령]]>=20), "O", AND(COUNTIF(표3[[#This Row],[주용도]],"<>*공동*"), COUNTIF(표3[[#This Row],[주용도]],"<>*단독*"), ISNUMBER(SEARCH("철",표3[[#This Row],[주구조]])), 표3[[#This Row],[건물연령]]>=30), "O", AND(COUNTIF(표3[[#This Row],[주용도]],"<>*공동*"), COUNTIF(표3[[#This Row],[주구조]],"<>*철*"), 표3[[#This Row],[건물연령]]>=20), "O", AND(COUNTIF(표3[[#This Row],[주용도]],"<>*공동*"), ISNUMBER(SEARCH("주택",표3[[#This Row],[주용도]])), 표3[[#This Row],[건물연령]]>=20), "O" ), "") )} | AG15: 철근콘크리트구조 | AI15: 공동주택 | AO15: 정행택 | AP15: 1099885738 | AQ15: 윤민숙 전화번호 | AR15: 75 | AS15: =IF( OR(표3[[#This Row],[생년월일]]="", ISBLANK(표3[[#This Row],[생년월일]])), "", IFERROR( _xlfn.LET( _xlpm.y, VALUE(표3[[#This Row],[생년월일]]), _xlpm.yyyy, IF(_xlpm.y<100, IF(_xlpm.y>25, 1900+_xlpm.y, 2000+_xlpm.y), _xlpm.y), _xlpm.age, YEAR(TODAY())-_xlpm.yyyy, IF( _xlpm.age<40,"40대 미만", IF(_xlpm.age<50,"40대", IF(_xlpm.age<60,"50대", IF(_xlpm.age<70,"60대", IF(_xlpm.age<80,"70대","80대 이상") )))) ), "") ) -> 50대 | AT15: 서울특별시 송파구 동남로8길 6 A동501호 | AU15: O | AW15: =IF(COUNTIF('설명회 참석자 명부'!$W$4:$W$29,표3[[#This Row],[성 명]])>0,"O","") | AX15: =_xlfn.XLOOKUP(표3[[#This Row],[성 명]],'설명회 참석자 명부'!$W$4:$W$29,'설명회 참석자 명부'!$X$4:$X$29,"") | BB15: O | BK15: =IFERROR(LEFT(표3[[#This Row],[주소]],FIND(" ",표3[[#This Row],[주소]])-1),"") -> 서울특별시 | BL15: =IFERROR(MID(표3[[#This Row],[주소]], FIND(" ", 표3[[#This Row],[주소]])+1, FIND(" ", 표3[[#This Row],[주소]], FIND(" ", 표3[[#This Row],[주소]])+1) - FIND(" ", 표3[[#This Row],[주소]])-1),"") -> 송파구 | BM15: =IFERROR(MID(표3[[#This Row],[주소]], FIND(" ", 표3[[#This Row],[주소]], FIND(" ", 표3[[#This Row],[주소]])+1)+1, FIND(" ", 표3[[#This Row],[주소]], FIND(" ", 표3[[#This Row],[주소]], FIND(" ", 표3[[#This Row],[주소]])+1)+1) - FIND(" ", 표3[[#This Row],[주소]], FIND(" ", 표3[[#This Row],[주소]])+1)-1),"") -> 동남로8길 | BY15: 다세대 | BZ15: 76.2 | CA15: 35.71 | CB15: 557000000 | CC15: 557000000 | CD15: =표3[[#This Row],[종전추정가액]]*1.5219 -> 847698300
B16: 10 | C16: 28 | D16: 1 | E16: 청송하이츠빌B | F16: 502 | R16: 0 | S16: 35.71 | T16: =표3[[#This Row],[편입면적]]/(SUM(표3[공부면적])) -> 0.0044615192 | W16: 76.2 | X16: 6.19 | Y16: 82.39 | AE16: {=IF(표3[[#This Row],[사용승인일자]]="","", IFERROR( _xlfn.IFS( AND(ISNUMBER(SEARCH("공동",표3[[#This Row],[주용도]])), ISNUMBER(SEARCH("철",표3[[#This Row],[주구조]])), 표3[[#This Row],[건물연령]]>=30), "O", AND(ISNUMBER(SEARCH("공동",표3[[#This Row],[주용도]])), COUNTIF(표3[[#This Row],[주구조]],"<>*철*"), 표3[[#This Row],[건물연령]]>=20), "O", AND(COUNTIF(표3[[#This Row],[주용도]],"<>*공동*"), COUNTIF(표3[[#This Row],[주용도]],"<>*단독*"), ISNUMBER(SEARCH("철",표3[[#This Row],[주구조]])), 표3[[#This Row],[건물연령]]>=30), "O", AND(COUNTIF(표3[[#This Row],[주용도]],"<>*공동*"), COUNTIF(표3[[#This Row],[주구조]],"<>*철*"), 표3[[#This Row],[건물연령]]>=20), "O", AND(COUNTIF(표3[[#This Row],[주용도]],"<>*공동*"), ISNUMBER(SEARCH("주택",표3[[#This Row],[주용도]])), 표3[[#This Row],[건물연령]]>=20), "O" ), "") )} | AG16: 철근콘크리트구조 | AI16: 공동주택 | AO16: 민경희 | AP16: 1023796112 | AR16: 59 | AS16: =IF( OR(표3[[#This Row],[생년월일]]="", ISBLANK(표3[[#This Row],[생년월일]])), "", IFERROR( _xlfn.LET( _xlpm.y, VALUE(표3[[#This Row],[생년월일]]), _xlpm.yyyy, IF(_xlpm.y<100, IF(_xlpm.y>25, 1900+_xlpm.y, 2000+_xlpm.y), _xlpm.y), _xlpm.age, YEAR(TODAY())-_xlpm.yyyy, IF( _xlpm.age<40,"40대 미만", IF(_xlpm.age<50,"40대", IF(_xlpm.age<60,"50대", IF(_xlpm.age<70,"60대", IF(_xlpm.age<80,"70대","80대 이상") )))) ), "") ) -> 60대 | AT16: 서울특별시 송파구 동남로8길 10, 502호(문정동, 청송하이츠빌라) | AU16: O | AW16: =IF(COUNTIF('설명회 참석자 명부'!$W$4:$W$29,표3[[#This Row],[성 명]])>0,"O","") | AX16: =_xlfn.XLOOKUP(표3[[#This Row],[성 명]],'설명회 참석자 명부'!$W$4:$W$29,'설명회 참석자 명부'!$X$4:$X$29,"") | BA16: O | BB16: O | BK16: =IFERROR(LEFT(표3[[#This Row],[주소]],FIND(" ",표3[[#This Row],[주소]])-1),"") -> 서울특별시 | BL16: =IFERROR(MID(표3[[#This Row],[주소]], FIND(" ", 표3[[#This Row],[주소]])+1, FIND(" ", 표3[[#This Row],[주소]], FIND(" ", 표3[[#This Row],[주소]])+1) - FIND(" ", 표3[[#This Row],[주소]])-1),"") -> 송파구 | BM16: =IFERROR(MID(표3[[#This Row],[주소]], FIND(" ", 표3[[#This Row],[주소]], FIND(" ", 표3[[#This Row],[주소]])+1)+1, FIND(" ", 표3[[#This Row],[주소]], FIND(" ", 표3[[#This Row],[주소]], FIND(" ", 표3[[#This Row],[주소]])+1)+1) - FIND(" ", 표3[[#This Row],[주소]], FIND(" ", 표3[[#This Row],[주소]])+1)-1),"") -> 동남로8길 | BY16: 다세대 | BZ16: 76.2 | CA16: 35.71 | CB16: 557000000 | CC16: 557000000 | CD16: =표3[[#This Row],[종전추정가액]]*1.5219 -> 847698300
C17: 28 | D17: 2 | E17: 청송하이츠빌 | F17: 0 | Q17: 대 | R17: 353.7 | T17: =표3[[#This Row],[편입면적]]/(SUM(표3[공부면적])) -> 0 | U17: O | Y17: 0 | Z17: 853.26 | AC17: 2002.08.05 | AD17: 23 | AE17: {=IF(표3[[#This Row],[사용승인일자]]="","", IFERROR( _xlfn.IFS( AND(ISNUMBER(SEARCH("공동",표3[[#This Row],[주용도]])), ISNUMBER(SEARCH("철",표3[[#This Row],[주구조]])), 표3[[#This Row],[건물연령]]>=30), "O", AND(ISNUMBER(SEARCH("공동",표3[[#This Row],[주용도]])), COUNTIF(표3[[#This Row],[주구조]],"<>*철*"), 표3[[#This Row],[건물연령]]>=20), "O", AND(COUNTIF(표3[[#This Row],[주용도]],"<>*공동*"), COUNTIF(표3[[#This Row],[주용도]],"<>*단독*"), ISNUMBER(SEARCH("철",표3[[#This Row],[주구조]])), 표3[[#This Row],[건물연령]]>=30), "O", AND(COUNTIF(표3[[#This Row],[주용도]],"<>*공동*"), COUNTIF(표3[[#This Row],[주구조]],"<>*철*"), 표3[[#This Row],[건물연령]]>=20), "O", AND(COUNTIF(표3[[#This Row],[주용도]],"<>*공동*"), ISNUMBER(SEARCH("주택",표3[[#This Row],[주용도]])), 표3[[#This Row],[건물연령]]>=20), "O" ), "") )} | AG17: 철근콘크리트구조 | AI17: 공동주택 | AM17: 5 | AN17: 1 | AS17: =IF( OR(표3[[#This Row],[생년월일]]="", ISBLANK(표3[[#This Row],[생년월일]])), "", IFERROR( _xlfn.LET( _xlpm.y, VALUE(표3[[#This Row],[생년월일]]), _xlpm.yyyy, IF(_xlpm.y<100, IF(_xlpm.y>25, 1900+_xlpm.y, 2000+_xlpm.y), _xlpm.y), _xlpm.age, YEAR(TODAY())-_xlpm.yyyy, IF( _xlpm.age<40,"40대 미만", IF(_xlpm.age<50,"40대", IF(_xlpm.age<60,"50대", IF(_xlpm.age<70,"60대", IF(_xlpm.age<80,"70대","80대 이상") )))) ), "") ) | AW17: =IF(COUNTIF('설명회 참석자 명부'!$W$4:$W$29,표3[[#This Row],[성 명]])>0,"O","") | AX17: =_xlfn.XLOOKUP(표3[[#This Row],[성 명]],'설명회 참석자 명부'!$W$4:$W$29,'설명회 참석자 명부'!$X$4:$X$29,"") -> 0 | BK17: =IFERROR(LEFT(표3[[#This Row],[주소]],FIND(" ",표3[[#This Row],[주소]])-1),"") | BL17: =IFERROR(MID(표3[[#This Row],[주소]], FIND(" ", 표3[[#This Row],[주소]])+1, FIND(" ", 표3[[#This Row],[주소]], FIND(" ", 표3[[#This Row],[주소]])+1) - FIND(" ", 표3[[#This Row],[주소]])-1),"") | BM17: =IFERROR(MID(표3[[#This Row],[주소]], FIND(" ", 표3[[#This Row],[주소]], FIND(" ", 표3[[#This Row],[주소]])+1)+1, FIND(" ", 표3[[#This Row],[주소]], FIND(" ", 표3[[#This Row],[주소]], FIND(" ", 표3[[#This Row],[주소]])+1)+1) - FIND(" ", 표3[[#This Row],[주소]], FIND(" ", 표3[[#This Row],[주소]])+1)-1),"") | CD17: =표3[[#This Row],[종전추정가액]]*1.5219 -> 0
B18: 11 | C18: 28 | D18: 2 | E18: 청송하이츠빌 | F18: 101 | K18: O | L18: O | M18: O | P18: [2026.04.13 17:04] 이민후 팀장: 금일 준비위원 회의시 동의서 제출 [2026.04.13 17:20] 이민후 팀장: 4-13 간담회 참석 | R18: 0 | S18: 62.45 | T18: =표3[[#This Row],[편입면적]]/(SUM(표3[공부면적])) -> 0.0078023488 | W18: 140.18 | X18: 10.53 | Y18: 150.71 | AE18: {=IF(표3[[#This Row],[사용승인일자]]="","", IFERROR( _xlfn.IFS( AND(ISNUMBER(SEARCH("공동",표3[[#This Row],[주용도]])), ISNUMBER(SEARCH("철",표3[[#This Row],[주구조]])), 표3[[#This Row],[건물연령]]>=30), "O", AND(ISNUMBER(SEARCH("공동",표3[[#This Row],[주용도]])), COUNTIF(표3[[#This Row],[주구조]],"<>*철*"), 표3[[#This Row],[건물연령]]>=20), "O", AND(COUNTIF(표3[[#This Row],[주용도]],"<>*공동*"), COUNTIF(표3[[#This Row],[주용도]],"<>*단독*"), ISNUMBER(SEARCH("철",표3[[#This Row],[주구조]])), 표3[[#This Row],[건물연령]]>=30), "O", AND(COUNTIF(표3[[#This Row],[주용도]],"<>*공동*"), COUNTIF(표3[[#This Row],[주구조]],"<>*철*"), 표3[[#This Row],[건물연령]]>=20), "O", AND(COUNTIF(표3[[#This Row],[주용도]],"<>*공동*"), ISNUMBER(SEARCH("주택",표3[[#This Row],[주용도]])), 표3[[#This Row],[건물연령]]>=20), "O" ), "") )} | AG18: 철근콘크리트구조 | AI18: 공동주택 | AO18: 김제각외1 | AP18: 1094840777 | AR18: 65 | AS18: =IF( OR(표3[[#This Row],[생년월일]]="", ISBLANK(표3[[#This Row],[생년월일]])), "", IFERROR( _xlfn.LET( _xlpm.y, VALUE(표3[[#This Row],[생년월일]]), _xlpm.yyyy, IF(_xlpm.y<100, IF(_xlpm.y>25, 1900+_xlpm.y, 2000+_xlpm.y), _xlpm.y), _xlpm.age, YEAR(TODAY())-_xlpm.yyyy, IF( _xlpm.age<40,"40대 미만", IF(_xlpm.age<50,"40대", IF(_xlpm.age<60,"50대", IF(_xlpm.age<70,"60대", IF(_xlpm.age<80,"70대","80대 이상") )))) ), "") ) -> 60대 | AT18: 경기도 용인시 수지구 용구대로2771번길68, 108동 701호 (죽전동,벽산타운1단지) | AV18: O | AW18: =IF(COUNTIF('설명회 참석자 명부'!$W$4:$W$29,표3[[#This Row],[성 명]])>0,"O","") | AX18: =_xlfn.XLOOKUP(표3[[#This Row],[성 명]],'설명회 참석자 명부'!$W$4:$W$29,'설명회 참석자 명부'!$X$4:$X$29,"") | BB18: O | BK18: =IFERROR(LEFT(표3[[#This Row],[주소]],FIND(" ",표3[[#This Row],[주소]])-1),"") -> 경기도 | BL18: =IFERROR(MID(표3[[#This Row],[주소]], FIND(" ", 표3[[#This Row],[주소]])+1, FIND(" ", 표3[[#This Row],[주소]], FIND(" ", 표3[[#This Row],[주소]])+1) - FIND(" ", 표3[[#This Row],[주소]])-1),"") -> 용인시 | BM18: =IFERROR(MID(표3[[#This Row],[주소]], FIND(" ", 표3[[#This Row],[주소]], FIND(" ", 표3[[#This Row],[주소]])+1)+1, FIND(" ", 표3[[#This Row],[주소]], FIND(" ", 표3[[#This Row],[주소]], FIND(" ", 표3[[#This Row],[주소]])+1)+1) - FIND(" ", 표3[[#This Row],[주소]], FIND(" ", 표3[[#This Row],[주소]])+1)-1),"") -> 수지구 | BY18: 소매점 | BZ18: 140.18 | CA18: 62.45 | CB18: 963000000 | CC18: 963000000 | CD18: =표3[[#This Row],[종전추정가액]]*1.5219 -> 1465589700
B19: 11 | C19: 28 | D19: 2 | E19: 청송하이츠빌 | F19: 102 | K19: O | L19: O | M19: O | P19: [2026.04.13 17:04] 이민후 팀장: 금일 준비위원 회의시 동의서 제출 [2026.04.13 17:20] 이민후 팀장: 4-13 간담회 참석 | R19: 0 | S19: 18.83 | T19: =표3[[#This Row],[편입면적]]/(SUM(표3[공부면적])) -> 0.0023525737 | W19: 42.28 | X19: 3.15 | Y19: 45.43 | AE19: {=IF(표3[[#This Row],[사용승인일자]]="","", IFERROR( _xlfn.IFS( AND(ISNUMBER(SEARCH("공동",표3[[#This Row],[주용도]])), ISNUMBER(SEARCH("철",표3[[#This Row],[주구조]])), 표3[[#This Row],[건물연령]]>=30), "O", AND(ISNUMBER(SEARCH("공동",표3[[#This Row],[주용도]])), COUNTIF(표3[[#This Row],[주구조]],"<>*철*"), 표3[[#This Row],[건물연령]]>=20), "O", AND(COUNTIF(표3[[#This Row],[주용도]],"<>*공동*"), COUNTIF(표3[[#This Row],[주용도]],"<>*단독*"), ISNUMBER(SEARCH("철",표3[[#This Row],[주구조]])), 표3[[#This Row],[건물연령]]>=30), "O", AND(COUNTIF(표3[[#This Row],[주용도]],"<>*공동*"), COUNTIF(표3[[#This Row],[주구조]],"<>*철*"), 표3[[#This Row],[건물연령]]>=20), "O", AND(COUNTIF(표3[[#This Row],[주용도]],"<>*공동*"), ISNUMBER(SEARCH("주택",표3[[#This Row],[주용도]])), 표3[[#This Row],[건물연령]]>=20), "O" ), "") )} | AG19: 철근콘크리트구조 | AI19: 공동주택 | AO19: 김제각외1 | AP19: 1044530114 | AS19: =IF( OR(표3[[#This Row],[생년월일]]="", ISBLANK(표3[[#This Row],[생년월일]])), "", IFERROR( _xlfn.LET( _xlpm.y, VALUE(표3[[#This Row],[생년월일]]), _xlpm.yyyy, IF(_xlpm.y<100, IF(_xlpm.y>25, 1900+_xlpm.y, 2000+_xlpm.y), _xlpm.y), _xlpm.age, YEAR(TODAY())-_xlpm.yyyy, IF( _xlpm.age<40,"40대 미만", IF(_xlpm.age<50,"40대", IF(_xlpm.age<60,"50대", IF(_xlpm.age<70,"60대", IF(_xlpm.age<80,"70대","80대 이상") )))) ), "") ) | AT19: 경기도 용인시 수지구 용구대로2771번길68, 108동 701호 (죽전동,벽산타운1단지) | AW19: =IF(COUNTIF('설명회 참석자 명부'!$W$4:$W$29,표3[[#This Row],[성 명]])>0,"O","") | AX19: =_xlfn.XLOOKUP(표3[[#This Row],[성 명]],'설명회 참석자 명부'!$W$4:$W$29,'설명회 참석자 명부'!$X$4:$X$29,"") | BB19: O | BK19: =IFERROR(LEFT(표3[[#This Row],[주소]],FIND(" ",표3[[#This Row],[주소]])-1),"") -> 경기도 | BL19: =IFERROR(MID(표3[[#This Row],[주소]], FIND(" ", 표3[[#This Row],[주소]])+1, FIND(" ", 표3[[#This Row],[주소]], FIND(" ", 표3[[#This Row],[주소]])+1) - FIND(" ", 표3[[#This Row],[주소]])-1),"") -> 용인시 | BM19: =IFERROR(MID(표3[[#This Row],[주소]], FIND(" ", 표3[[#This Row],[주소]], FIND(" ", 표3[[#This Row],[주소]])+1)+1, FIND(" ", 표3[[#This Row],[주소]], FIND(" ", 표3[[#This Row],[주소]], FIND(" ", 표3[[#This Row],[주소]])+1)+1) - FIND(" ", 표3[[#This Row],[주소]], FIND(" ", 표3[[#This Row],[주소]])+1)-1),"") -> 수지구 | BY19: 소매점 | BZ19: 42.28 | CA19: 18.83 | CB19: 290000000 | CC19: 290000000 | CD19: =표3[[#This Row],[종전추정가액]]*1.5219 -> 441351000
B20: 12 | C20: 28 | D20: 2 | E20: 청송하이츠빌 | F20: 201 | R20: 0 | S20: 34.05 | T20: =표3[[#This Row],[편입면적]]/(SUM(표3[공부면적])) -> 0.0042541229 | W20: 76.44 | X20: 5.7 | Y20: 82.14 | AE20: {=IF(표3[[#This Row],[사용승인일자]]="","", IFERROR( _xlfn.IFS( AND(ISNUMBER(SEARCH("공동",표3[[#This Row],[주용도]])), ISNUMBER(SEARCH("철",표3[[#This Row],[주구조]])), 표3[[#This Row],[건물연령]]>=30), "O", AND(ISNUMBER(SEARCH("공동",표3[[#This Row],[주용도]])), COUNTIF(표3[[#This Row],[주구조]],"<>*철*"), 표3[[#This Row],[건물연령]]>=20), "O", AND(COUNTIF(표3[[#This Row],[주용도]],"<>*공동*"), COUNTIF(표3[[#This Row],[주용도]],"<>*단독*"), ISNUMBER(SEARCH("철",표3[[#This Row],[주구조]])), 표3[[#This Row],[건물연령]]>=30), "O", AND(COUNTIF(표3[[#This Row],[주용도]],"<>*공동*"), COUNTIF(표3[[#This Row],[주구조]],"<>*철*"), 표3[[#This Row],[건물연령]]>=20), "O", AND(COUNTIF(표3[[#This Row],[주용도]],"<>*공동*"), ISNUMBER(SEARCH("주택",표3[[#This Row],[주용도]])), 표3[[#This Row],[건물연령]]>=20), "O" ), "") )} | AG20: 철근콘크리트구조 | AI20: 공동주택 | AO20: 이지은 | AP20: 1090234936 | AR20: 64 | AS20: =IF( OR(표3[[#This Row],[생년월일]]="", ISBLANK(표3[[#This Row],[생년월일]])), "", IFERROR( _xlfn.LET( _xlpm.y, VALUE(표3[[#This Row],[생년월일]]), _xlpm.yyyy, IF(_xlpm.y<100, IF(_xlpm.y>25, 1900+_xlpm.y, 2000+_xlpm.y), _xlpm.y), _xlpm.age, YEAR(TODAY())-_xlpm.yyyy, IF( _xlpm.age<40,"40대 미만", IF(_xlpm.age<50,"40대", IF(_xlpm.age<60,"50대", IF(_xlpm.age<70,"60대", IF(_xlpm.age<80,"70대","80대 이상") )))) ), "") ) -> 60대 | AT20: 서울 송파구 문정동 28-2 청송하이츠빌 201호 | AW20: =IF(COUNTIF('설명회 참석자 명부'!$W$4:$W$29,표3[[#This Row],[성 명]])>0,"O","") | AX20: =_xlfn.XLOOKUP(표3[[#This Row],[성 명]],'설명회 참석자 명부'!$W$4:$W$29,'설명회 참석자 명부'!$X$4:$X$29,"") | BK20: =IFERROR(LEFT(표3[[#This Row],[주소]],FIND(" ",표3[[#This Row],[주소]])-1),"") -> 서울 | BL20: =IFERROR(MID(표3[[#This Row],[주소]], FIND(" ", 표3[[#This Row],[주소]])+1, FIND(" ", 표3[[#This Row],[주소]], FIND(" ", 표3[[#This Row],[주소]])+1) - FIND(" ", 표3[[#This Row],[주소]])-1),"") -> 송파구 | BM20: =IFERROR(MID(표3[[#This Row],[주소]], FIND(" ", 표3[[#This Row],[주소]], FIND(" ", 표3[[#This Row],[주소]])+1)+1, FIND(" ", 표3[[#This Row],[주소]], FIND(" ", 표3[[#This Row],[주소]], FIND(" ", 표3[[#This Row],[주소]])+1)+1) - FIND(" ", 표3[[#This Row],[주소]], FIND(" ", 표3[[#This Row],[주소]])+1)-1),"") -> 문정동 | BY20: 다세대 | BZ20: 76.44 | CA20: 34.05 | CB20: 539000000 | CC20: 539000000 | CD20: =표3[[#This Row],[종전추정가액]]*1.5219 -> 820304100
B21: 13 | C21: 28 | D21: 2 | E21: 청송하이츠빌 | F21: 202 | R21: 0 | S21: 34.05 | T21: =표3[[#This Row],[편입면적]]/(SUM(표3[공부면적])) -> 0.0042541229 | W21: 76.44 | X21: 5.7 | Y21: 82.14 | AE21: {=IF(표3[[#This Row],[사용승인일자]]="","", IFERROR( _xlfn.IFS( AND(ISNUMBER(SEARCH("공동",표3[[#This Row],[주용도]])), ISNUMBER(SEARCH("철",표3[[#This Row],[주구조]])), 표3[[#This Row],[건물연령]]>=30), "O", AND(ISNUMBER(SEARCH("공동",표3[[#This Row],[주용도]])), COUNTIF(표3[[#This Row],[주구조]],"<>*철*"), 표3[[#This Row],[건물연령]]>=20), "O", AND(COUNTIF(표3[[#This Row],[주용도]],"<>*공동*"), COUNTIF(표3[[#This Row],[주용도]],"<>*단독*"), ISNUMBER(SEARCH("철",표3[[#This Row],[주구조]])), 표3[[#This Row],[건물연령]]>=30), "O", AND(COUNTIF(표3[[#This Row],[주용도]],"<>*공동*"), COUNTIF(표3[[#This Row],[주구조]],"<>*철*"), 표3[[#This Row],[건물연령]]>=20), "O", AND(COUNTIF(표3[[#This Row],[주용도]],"<>*공동*"), ISNUMBER(SEARCH("주택",표3[[#This Row],[주용도]])), 표3[[#This Row],[건물연령]]>=20), "O" ), "") )} | AG21: 철근콘크리트구조 | AI21: 공동주택 | AO21: 강재형 | AP21: 1052729620 | AR21: 60 | AS21: =IF( OR(표3[[#This Row],[생년월일]]="", ISBLANK(표3[[#This Row],[생년월일]])), "", IFERROR( _xlfn.LET( _xlpm.y, VALUE(표3[[#This Row],[생년월일]]), _xlpm.yyyy, IF(_xlpm.y<100, IF(_xlpm.y>25, 1900+_xlpm.y, 2000+_xlpm.y), _xlpm.y), _xlpm.age, YEAR(TODAY())-_xlpm.yyyy, IF( _xlpm.age<40,"40대 미만", IF(_xlpm.age<50,"40대", IF(_xlpm.age<60,"50대", IF(_xlpm.age<70,"60대", IF(_xlpm.age<80,"70대","80대 이상") )))) ), "") ) -> 60대 | AT21: 서울 송파구 문정동 28-2 청송빌라 202호 | AU21: O | AW21: =IF(COUNTIF('설명회 참석자 명부'!$W$4:$W$29,표3[[#This Row],[성 명]])>0,"O","") | BA21: O | BB21: O | BK21: =IFERROR(LEFT(표3[[#This Row],[주소]],FIND(" ",표3[[#This Row],[주소]])-1),"") -> 서울 | BL21: =IFERROR(MID(표3[[#This Row],[주소]], FIND(" ", 표3[[#This Row],[주소]])+1, FIND(" ", 표3[[#This Row],[주소]], FIND(" ", 표3[[#This Row],[주소]])+1) - FIND(" ", 표3[[#This Row],[주소]])-1),"") -> 송파구 | BM21: =IFERROR(MID(표3[[#This Row],[주소]], FIND(" ", 표3[[#This Row],[주소]], FIND(" ", 표3[[#This Row],[주소]])+1)+1, FIND(" ", 표3[[#This Row],[주소]], FIND(" ", 표3[[#This Row],[주소]], FIND(" ", 표3[[#This Row],[주소]])+1)+1) - FIND(" ", 표3[[#This Row],[주소]], FIND(" ", 표3[[#This Row],[주소]])+1)-1),"") -> 문정동 | BY21: 다세대 | BZ21: 76.44 | CA21: 34.05 | CB21: 539000000 | CC21: 539000000 | CD21: =표3[[#This Row],[종전추정가액]]*1.5219 -> 820304100
B22: 14 | C22: 28 | D22: 2 | E22: 청송하이츠빌 | F22: 301 | P22: [2026.04.14 13:33] 최광식 부사장: 4/14 문주영님 어머님 방문. 딸은 직장인이라 방문이 어려움. | R22: 0 | S22: 34.05 | T22: =표3[[#This Row],[편입면적]]/(SUM(표3[공부면적])) -> 0.0042541229 | W22: 76.44 | X22: 5.7 | Y22: 82.14 | AE22: {=IF(표3[[#This Row],[사용승인일자]]="","", IFERROR( _xlfn.IFS( AND(ISNUMBER(SEARCH("공동",표3[[#This Row],[주용도]])), ISNUMBER(SEARCH("철",표3[[#This Row],[주구조]])), 표3[[#This Row],[건물연령]]>=30), "O", AND(ISNUMBER(SEARCH("공동",표3[[#This Row],[주용도]])), COUNTIF(표3[[#This Row],[주구조]],"<>*철*"), 표3[[#This Row],[건물연령]]>=20), "O", AND(COUNTIF(표3[[#This Row],[주용도]],"<>*공동*"), COUNTIF(표3[[#This Row],[주용도]],"<>*단독*"), ISNUMBER(SEARCH("철",표3[[#This Row],[주구조]])), 표3[[#This Row],[건물연령]]>=30), "O", AND(COUNTIF(표3[[#This Row],[주용도]],"<>*공동*"), COUNTIF(표3[[#This Row],[주구조]],"<>*철*"), 표3[[#This Row],[건물연령]]>=20), "O", AND(COUNTIF(표3[[#This Row],[주용도]],"<>*공동*"), ISNUMBER(SEARCH("주택",표3[[#This Row],[주용도]])), 표3[[#This Row],[건물연령]]>=20), "O" ), "") )} | AG22: 철근콘크리트구조 | AI22: 공동주택 | AO22: 문주영외1 | AP22: 1088667967 | AR22: 83 | AS22: =IF( OR(표3[[#This Row],[생년월일]]="", ISBLANK(표3[[#This Row],[생년월일]])), "", IFERROR( _xlfn.LET( _xlpm.y, VALUE(표3[[#This Row],[생년월일]]), _xlpm.yyyy, IF(_xlpm.y<100, IF(_xlpm.y>25, 1900+_xlpm.y, 2000+_xlpm.y), _xlpm.y), _xlpm.age, YEAR(TODAY())-_xlpm.yyyy, IF( _xlpm.age<40,"40대 미만", IF(_xlpm.age<50,"40대", IF(_xlpm.age<60,"50대", IF(_xlpm.age<70,"60대", IF(_xlpm.age<80,"70대","80대 이상") )))) ), "") ) -> 40대 | AT22: 문정로55 102동702호 | AU22: O | AW22: =IF(COUNTIF('설명회 참석자 명부'!$W$4:$W$29,표3[[#This Row],[성 명]])>0,"O","") | AX22: =_xlfn.XLOOKUP(표3[[#This Row],[성 명]],'설명회 참석자 명부'!$W$4:$W$29,'설명회 참석자 명부'!$X$4:$X$29,"") | BB22: O | BK22: =IFERROR(LEFT(표3[[#This Row],[주소]],FIND(" ",표3[[#This Row],[주소]])-1),"") -> 문정로55 | BL22: =IFERROR(MID(표3[[#This Row],[주소]], FIND(" ", 표3[[#This Row],[주소]])+1, FIND(" ", 표3[[#This Row],[주소]], FIND(" ", 표3[[#This Row],[주소]])+1) - FIND(" ", 표3[[#This Row],[주소]])-1),"") | BM22: =IFERROR(MID(표3[[#This Row],[주소]], FIND(" ", 표3[[#This Row],[주소]], FIND(" ", 표3[[#This Row],[주소]])+1)+1, FIND(" ", 표3[[#This Row],[주소]], FIND(" ", 표3[[#This Row],[주소]], FIND(" ", 표3[[#This Row],[주소]])+1)+1) - FIND(" ", 표3[[#This Row],[주소]], FIND(" ", 표3[[#This Row],[주소]])+1)-1),"") | BY22: 다세대 | BZ22: 76.44 | CA22: 34.05 | CB22: 544000000 | CC22: 544000000 | CD22: =표3[[#This Row],[종전추정가액]]*1.5219 -> 827913600
B23: 15 | C23: 28 | D23: 2 | E23: 청송하이츠빌 | F23: 302 | K23: O | L23: O | M23: O | P23: [2026.04.13 09:49] 이민후 팀장: 3차설명회 당일 동의 [2026.04.13 17:19] 이민후 팀장: 4-13 간담회 참석 | R23: 0 | S23: 34.05 | T23: =표3[[#This Row],[편입면적]]/(SUM(표3[공부면적])) -> 0.0042541229 | W23: 76.44 | X23: 5.7 | Y23: 82.14 | AE23: {=IF(표3[[#This Row],[사용승인일자]]="","", IFERROR( _xlfn.IFS( AND(ISNUMBER(SEARCH("공동",표3[[#This Row],[주용도]])), ISNUMBER(SEARCH("철",표3[[#This Row],[주구조]])), 표3[[#This Row],[건물연령]]>=30), "O", AND(ISNUMBER(SEARCH("공동",표3[[#This Row],[주용도]])), COUNTIF(표3[[#This Row],[주구조]],"<>*철*"), 표3[[#This Row],[건물연령]]>=20), "O", AND(COUNTIF(표3[[#This Row],[주용도]],"<>*공동*"), COUNTIF(표3[[#This Row],[주용도]],"<>*단독*"), ISNUMBER(SEARCH("철",표3[[#This Row],[주구조]])), 표3[[#This Row],[건물연령]]>=30), "O", AND(COUNTIF(표3[[#This Row],[주용도]],"<>*공동*"), COUNTIF(표3[[#This Row],[주구조]],"<>*철*"), 표3[[#This Row],[건물연령]]>=20), "O", AND(COUNTIF(표3[[#This Row],[주용도]],"<>*공동*"), ISNUMBER(SEARCH("주택",표3[[#This Row],[주용도]])), 표3[[#This Row],[건물연령]]>=20), "O" ), "") )} | AG23: 철근콘크리트구조 | AI23: 공동주택 | AO23: 서용숙 | AP23: 010-5232-2332 010-9183-6367 | AQ23: 준비위원 남편 최영훈 | AR23: 67 | AS23: =IF( OR(표3[[#This Row],[생년월일]]="", ISBLANK(표3[[#This Row],[생년월일]])), "", IFERROR( _xlfn.LET( _xlpm.y, VALUE(표3[[#This Row],[생년월일]]), _xlpm.yyyy, IF(_xlpm.y<100, IF(_xlpm.y>25, 1900+_xlpm.y, 2000+_xlpm.y), _xlpm.y), _xlpm.age, YEAR(TODAY())-_xlpm.yyyy, IF( _xlpm.age<40,"40대 미만", IF(_xlpm.age<50,"40대", IF(_xlpm.age<60,"50대", IF(_xlpm.age<70,"60대", IF(_xlpm.age<80,"70대","80대 이상") )))) ), "") ) -> 50대 | AT23: 서울특별시 송파구 문정동 28-2 청송빌라 에이-302 | AU23: O | AV23: O | AW23: =IF(COUNTIF('설명회 참석자 명부'!$W$4:$W$29,표3[[#This Row],[성 명]])>0,"O","") | AX23: =_xlfn.XLOOKUP(표3[[#This Row],[성 명]],'설명회 참석자 명부'!$W$4:$W$29,'설명회 참석자 명부'!$X$4:$X$29,"") | BB23: O | BK23: =IFERROR(LEFT(표3[[#This Row],[주소]],FIND(" ",표3[[#This Row],[주소]])-1),"") -> 서울특별시 | BL23: =IFERROR(MID(표3[[#This Row],[주소]], FIND(" ", 표3[[#This Row],[주소]])+1, FIND(" ", 표3[[#This Row],[주소]], FIND(" ", 표3[[#This Row],[주소]])+1) - FIND(" ", 표3[[#This Row],[주소]])-1),"") -> 송파구 | BM23: =IFERROR(MID(표3[[#This Row],[주소]], FIND(" ", 표3[[#This Row],[주소]], FIND(" ", 표3[[#This Row],[주소]])+1)+1, FIND(" ", 표3[[#This Row],[주소]], FIND(" ", 표3[[#This Row],[주소]], FIND(" ", 표3[[#This Row],[주소]])+1)+1) - FIND(" ", 표3[[#This Row],[주소]], FIND(" ", 표3[[#This Row],[주소]])+1)-1),"") -> 문정동 | BY23: 다세대 | BZ23: 76.44 | CA23: 34.05 | CB23: 544000000 | CC23: 544000000 | CD23: =표3[[#This Row],[종전추정가액]]*1.5219 -> 827913600
B24: 16 | C24: 28 | D24: 2 | E24: 청송하이츠빌 | F24: 401 | K24: O | L24: O | M24: O | P24: [2026.04.13 09:49] 이민후 팀장: 3차설명회 당일 동의 | R24: 0 | S24: 34.05 | T24: =표3[[#This Row],[편입면적]]/(SUM(표3[공부면적])) -> 0.0042541229 | W24: 76.44 | X24: 5.7 | Y24: 82.14 | AE24: {=IF(표3[[#This Row],[사용승인일자]]="","", IFERROR( _xlfn.IFS( AND(ISNUMBER(SEARCH("공동",표3[[#This Row],[주용도]])), ISNUMBER(SEARCH("철",표3[[#This Row],[주구조]])), 표3[[#This Row],[건물연령]]>=30), "O", AND(ISNUMBER(SEARCH("공동",표3[[#This Row],[주용도]])), COUNTIF(표3[[#This Row],[주구조]],"<>*철*"), 표3[[#This Row],[건물연령]]>=20), "O", AND(COUNTIF(표3[[#This Row],[주용도]],"<>*공동*"), COUNTIF(표3[[#This Row],[주용도]],"<>*단독*"), ISNUMBER(SEARCH("철",표3[[#This Row],[주구조]])), 표3[[#This Row],[건물연령]]>=30), "O", AND(COUNTIF(표3[[#This Row],[주용도]],"<>*공동*"), COUNTIF(표3[[#This Row],[주구조]],"<>*철*"), 표3[[#This Row],[건물연령]]>=20), "O", AND(COUNTIF(표3[[#This Row],[주용도]],"<>*공동*"), ISNUMBER(SEARCH("주택",표3[[#This Row],[주용도]])), 표3[[#This Row],[건물연령]]>=20), "O" ), "") )} | AG24: 철근콘크리트구조 | AI24: 공동주택 | AO24: 변철종 | AP24: 1053684927 | AR24: 70 | AS24: =IF( OR(표3[[#This Row],[생년월일]]="", ISBLANK(표3[[#This Row],[생년월일]])), "", IFERROR( _xlfn.LET( _xlpm.y, VALUE(표3[[#This Row],[생년월일]]), _xlpm.yyyy, IF(_xlpm.y<100, IF(_xlpm.y>25, 1900+_xlpm.y, 2000+_xlpm.y), _xlpm.y), _xlpm.age, YEAR(TODAY())-_xlpm.yyyy, IF( _xlpm.age<40,"40대 미만", IF(_xlpm.age<50,"40대", IF(_xlpm.age<60,"50대", IF(_xlpm.age<70,"60대", IF(_xlpm.age<80,"70대","80대 이상") )))) ), "") ) -> 50대 | AT24: 서울특별시 송파구 동남로8길 6 ,401호(문정동) | AW24: =IF(COUNTIF('설명회 참석자 명부'!$W$4:$W$29,표3[[#This Row],[성 명]])>0,"O","") | AX24: =_xlfn.XLOOKUP(표3[[#This Row],[성 명]],'설명회 참석자 명부'!$W$4:$W$29,'설명회 참석자 명부'!$X$4:$X$29,"") | BB24: O | BK24: =IFERROR(LEFT(표3[[#This Row],[주소]],FIND(" ",표3[[#This Row],[주소]])-1),"") -> 서울특별시 | BL24: =IFERROR(MID(표3[[#This Row],[주소]], FIND(" ", 표3[[#This Row],[주소]])+1, FIND(" ", 표3[[#This Row],[주소]], FIND(" ", 표3[[#This Row],[주소]])+1) - FIND(" ", 표3[[#This Row],[주소]])-1),"") -> 송파구 | BM24: =IFERROR(MID(표3[[#This Row],[주소]], FIND(" ", 표3[[#This Row],[주소]], FIND(" ", 표3[[#This Row],[주소]])+1)+1, FIND(" ", 표3[[#This Row],[주소]], FIND(" ", 표3[[#This Row],[주소]], FIND(" ", 표3[[#This Row],[주소]])+1)+1) - FIND(" ", 표3[[#This Row],[주소]], FIND(" ", 표3[[#This Row],[주소]])+1)-1),"") -> 동남로8길 | BY24: 다세대 | BZ24: 76.44 | CA24: 34.05 | CB24: 544000000 | CC24: 544000000 | CD24: =표3[[#This Row],[종전추정가액]]*1.5219 -> 827913600
